path = /home/ldoyen--/Project_42/webserv/webserv_github/html/cgi/python && outfile cgi= webserv_out5host516777343port5167773434250
getexecutepath = /bin/python3
getcgifile = welcome.py
starting execve
==249724== Memcheck, a memory error detector
==249724== Copyright (C) 2002-2017, and GNU GPL'd, by Julian Seward et al.
==249724== Using Valgrind-3.18.1 and LibVEX; rerun with -h for copyright info
==249724== Command: /bin/python3 welcome.py
==249724== 
==249724== 
==249724== FILE DESCRIPTORS: 3 open (3 std) at exit.
==249724== 
==249724== HEAP SUMMARY:
==249724==     in use at exit: 115,753 bytes in 112 blocks
==249724==   total heap usage: 3,639 allocs, 3,527 frees, 7,296,503 bytes allocated
==249724== 
==249724== 71 bytes in 2 blocks are still reachable in loss record 1 of 99
==249724==    at 0x4848899: malloc (in /usr/libexec/valgrind/vgpreload_memcheck-amd64-linux.so)
==249724==    by 0x40271DF: malloc (rtld-malloc.h:56)
==249724==    by 0x40271DF: strdup (strdup.c:42)
==249724==    by 0x4016A66: _dl_load_cache_lookup (dl-cache.c:527)
==249724==    by 0x400A981: _dl_map_object (dl-load.c:2193)
==249724==    by 0x4003494: openaux (dl-deps.c:64)
==249724==    by 0x49E8A97: _dl_catch_exception (dl-error-skeleton.c:208)
==249724==    by 0x4003C7B: _dl_map_object_deps (dl-deps.c:248)
==249724==    by 0x400EA0E: dl_open_worker_begin (dl-open.c:592)
==249724==    by 0x49E8A97: _dl_catch_exception (dl-error-skeleton.c:208)
==249724==    by 0x400DF99: dl_open_worker (dl-open.c:782)
==249724==    by 0x49E8A97: _dl_catch_exception (dl-error-skeleton.c:208)
==249724==    by 0x400E34D: _dl_open (dl-open.c:883)
==249724== 
==249724== 71 bytes in 2 blocks are still reachable in loss record 2 of 99
==249724==    at 0x4848899: malloc (in /usr/libexec/valgrind/vgpreload_memcheck-amd64-linux.so)
==249724==    by 0x400DD20: malloc (rtld-malloc.h:56)
==249724==    by 0x400DD20: _dl_new_object (dl-object.c:199)
==249724==    by 0x4008C82: _dl_map_object_from_fd (dl-load.c:1063)
==249724==    by 0x400A600: _dl_map_object (dl-load.c:2327)
==249724==    by 0x4003494: openaux (dl-deps.c:64)
==249724==    by 0x49E8A97: _dl_catch_exception (dl-error-skeleton.c:208)
==249724==    by 0x4003C7B: _dl_map_object_deps (dl-deps.c:248)
==249724==    by 0x400EA0E: dl_open_worker_begin (dl-open.c:592)
==249724==    by 0x49E8A97: _dl_catch_exception (dl-error-skeleton.c:208)
==249724==    by 0x400DF99: dl_open_worker (dl-open.c:782)
==249724==    by 0x49E8A97: _dl_catch_exception (dl-error-skeleton.c:208)
==249724==    by 0x400E34D: _dl_open (dl-open.c:883)
==249724== 
==249724== 139 bytes in 2 blocks are still reachable in loss record 3 of 99
==249724==    at 0x4848899: malloc (in /usr/libexec/valgrind/vgpreload_memcheck-amd64-linux.so)
==249724==    by 0x40271DF: malloc (rtld-malloc.h:56)
==249724==    by 0x40271DF: strdup (strdup.c:42)
==249724==    by 0x400A588: _dl_map_object (dl-load.c:2259)
==249724==    by 0x400E9A8: dl_open_worker_begin (dl-open.c:534)
==249724==    by 0x49E8A97: _dl_catch_exception (dl-error-skeleton.c:208)
==249724==    by 0x400DF99: dl_open_worker (dl-open.c:782)
==249724==    by 0x49E8A97: _dl_catch_exception (dl-error-skeleton.c:208)
==249724==    by 0x400E34D: _dl_open (dl-open.c:883)
==249724==    by 0x490463B: dlopen_doit (dlopen.c:56)
==249724==    by 0x49E8A97: _dl_catch_exception (dl-error-skeleton.c:208)
==249724==    by 0x49E8B62: _dl_catch_error (dl-error-skeleton.c:227)
==249724==    by 0x490412D: _dlerror_run (dlerror.c:138)
==249724== 
==249724== 139 bytes in 2 blocks are still reachable in loss record 4 of 99
==249724==    at 0x4848899: malloc (in /usr/libexec/valgrind/vgpreload_memcheck-amd64-linux.so)
==249724==    by 0x400DD20: malloc (rtld-malloc.h:56)
==249724==    by 0x400DD20: _dl_new_object (dl-object.c:199)
==249724==    by 0x4008C82: _dl_map_object_from_fd (dl-load.c:1063)
==249724==    by 0x400A600: _dl_map_object (dl-load.c:2327)
==249724==    by 0x400E9A8: dl_open_worker_begin (dl-open.c:534)
==249724==    by 0x49E8A97: _dl_catch_exception (dl-error-skeleton.c:208)
==249724==    by 0x400DF99: dl_open_worker (dl-open.c:782)
==249724==    by 0x49E8A97: _dl_catch_exception (dl-error-skeleton.c:208)
==249724==    by 0x400E34D: _dl_open (dl-open.c:883)
==249724==    by 0x490463B: dlopen_doit (dlopen.c:56)
==249724==    by 0x49E8A97: _dl_catch_exception (dl-error-skeleton.c:208)
==249724==    by 0x49E8B62: _dl_catch_error (dl-error-skeleton.c:227)
==249724== 
==249724== 516 bytes in 1 blocks are still reachable in loss record 5 of 99
==249724==    at 0x4848899: malloc (in /usr/libexec/valgrind/vgpreload_memcheck-amd64-linux.so)
==249724==    by 0x5C7F61: PyUnicode_FromString (in /usr/bin/python3.10)
==249724==    by 0x5DAF1C: PyType_Ready (in /usr/bin/python3.10)
==249724==    by 0x6F21F9: ??? (in /usr/bin/python3.10)
==249724==    by 0x6C3B38: ??? (in /usr/bin/python3.10)
==249724==    by 0x63082B: ??? (in /usr/bin/python3.10)
==249724==    by 0x6BF551: Py_InitializeFromConfig (in /usr/bin/python3.10)
==249724==    by 0x704415: ??? (in /usr/bin/python3.10)
==249724==    by 0x704470: ??? (in /usr/bin/python3.10)
==249724==    by 0x7044BC: Py_BytesMain (in /usr/bin/python3.10)
==249724==    by 0x489DD8F: (below main) (libc_start_call_main.h:58)
==249724== 
==249724== 545 bytes in 1 blocks are still reachable in loss record 6 of 99
==249724==    at 0x4848899: malloc (in /usr/libexec/valgrind/vgpreload_memcheck-amd64-linux.so)
==249724==    by 0x5C7F61: PyUnicode_FromString (in /usr/bin/python3.10)
==249724==    by 0x5DAF1C: PyType_Ready (in /usr/bin/python3.10)
==249724==    by 0x6C37B6: PyModule_AddType (in /usr/bin/python3.10)
==249724==    by 0x69D32D: PyInit__io (in /usr/bin/python3.10)
==249724==    by 0x6CA547: ??? (in /usr/bin/python3.10)
==249724==    by 0x6CA60D: ??? (in /usr/bin/python3.10)
==249724==    by 0x53B136: ??? (in /usr/bin/python3.10)
==249724==    by 0x628A39: PyObject_Call (in /usr/bin/python3.10)
==249724==    by 0x5AFA8D: _PyEval_EvalFrameDefault (in /usr/bin/python3.10)
==249724==    by 0x628D5F: _PyFunction_Vectorcall (in /usr/bin/python3.10)
==249724==    by 0x5A9C1A: _PyEval_EvalFrameDefault (in /usr/bin/python3.10)
==249724== 
==249724== 561 bytes in 1 blocks are still reachable in loss record 7 of 99
==249724==    at 0x4848899: malloc (in /usr/libexec/valgrind/vgpreload_memcheck-amd64-linux.so)
==249724==    by 0x5C7F61: PyUnicode_FromString (in /usr/bin/python3.10)
==249724==    by 0x5DAF1C: PyType_Ready (in /usr/bin/python3.10)
==249724==    by 0x6F1DAF: ??? (in /usr/bin/python3.10)
==249724==    by 0x6C3B38: ??? (in /usr/bin/python3.10)
==249724==    by 0x63082B: ??? (in /usr/bin/python3.10)
==249724==    by 0x6BF551: Py_InitializeFromConfig (in /usr/bin/python3.10)
==249724==    by 0x704415: ??? (in /usr/bin/python3.10)
==249724==    by 0x704470: ??? (in /usr/bin/python3.10)
==249724==    by 0x7044BC: Py_BytesMain (in /usr/bin/python3.10)
==249724==    by 0x489DD8F: (below main) (libc_start_call_main.h:58)
==249724== 
==249724== 567 bytes in 1 blocks are still reachable in loss record 8 of 99
==249724==    at 0x4848899: malloc (in /usr/libexec/valgrind/vgpreload_memcheck-amd64-linux.so)
==249724==    by 0x5C7F61: PyUnicode_FromString (in /usr/bin/python3.10)
==249724==    by 0x5DAF1C: PyType_Ready (in /usr/bin/python3.10)
==249724==    by 0x6C498B: ??? (in /usr/bin/python3.10)
==249724==    by 0x63082B: ??? (in /usr/bin/python3.10)
==249724==    by 0x6BF551: Py_InitializeFromConfig (in /usr/bin/python3.10)
==249724==    by 0x704415: ??? (in /usr/bin/python3.10)
==249724==    by 0x704470: ??? (in /usr/bin/python3.10)
==249724==    by 0x7044BC: Py_BytesMain (in /usr/bin/python3.10)
==249724==    by 0x489DD8F: (below main) (libc_start_call_main.h:58)
==249724== 
==249724== 576 bytes in 1 blocks are still reachable in loss record 9 of 99
==249724==    at 0x4848899: malloc (in /usr/libexec/valgrind/vgpreload_memcheck-amd64-linux.so)
==249724==    by 0x5F2EB0: PyObject_Malloc (in /usr/bin/python3.10)
==249724==    by 0x60211C: ??? (in /usr/bin/python3.10)
==249724==    by 0x5FF185: PyDict_SetDefault (in /usr/bin/python3.10)
==249724==    by 0x5DADF5: PyType_Ready (in /usr/bin/python3.10)
==249724==    by 0x6F1D79: ??? (in /usr/bin/python3.10)
==249724==    by 0x6C3B38: ??? (in /usr/bin/python3.10)
==249724==    by 0x63082B: ??? (in /usr/bin/python3.10)
==249724==    by 0x6BF551: Py_InitializeFromConfig (in /usr/bin/python3.10)
==249724==    by 0x704415: ??? (in /usr/bin/python3.10)
==249724==    by 0x704470: ??? (in /usr/bin/python3.10)
==249724==    by 0x7044BC: Py_BytesMain (in /usr/bin/python3.10)
==249724== 
==249724== 576 bytes in 1 blocks are still reachable in loss record 10 of 99
==249724==    at 0x4848899: malloc (in /usr/libexec/valgrind/vgpreload_memcheck-amd64-linux.so)
==249724==    by 0x5F2EB0: PyObject_Malloc (in /usr/bin/python3.10)
==249724==    by 0x60211C: ??? (in /usr/bin/python3.10)
==249724==    by 0x5FF185: PyDict_SetDefault (in /usr/bin/python3.10)
==249724==    by 0x5DA17B: PyType_Ready (in /usr/bin/python3.10)
==249724==    by 0x6F1DE5: ??? (in /usr/bin/python3.10)
==249724==    by 0x6C3B38: ??? (in /usr/bin/python3.10)
==249724==    by 0x63082B: ??? (in /usr/bin/python3.10)
==249724==    by 0x6BF551: Py_InitializeFromConfig (in /usr/bin/python3.10)
==249724==    by 0x704415: ??? (in /usr/bin/python3.10)
==249724==    by 0x704470: ??? (in /usr/bin/python3.10)
==249724==    by 0x7044BC: Py_BytesMain (in /usr/bin/python3.10)
==249724== 
==249724== 576 bytes in 1 blocks are still reachable in loss record 11 of 99
==249724==    at 0x4848899: malloc (in /usr/libexec/valgrind/vgpreload_memcheck-amd64-linux.so)
==249724==    by 0x5F2EB0: PyObject_Malloc (in /usr/bin/python3.10)
==249724==    by 0x60211C: ??? (in /usr/bin/python3.10)
==249724==    by 0x603263: PyDict_SetItem (in /usr/bin/python3.10)
==249724==    by 0x5DAF3C: PyType_Ready (in /usr/bin/python3.10)
==249724==    by 0x6F1E2D: ??? (in /usr/bin/python3.10)
==249724==    by 0x6C3B38: ??? (in /usr/bin/python3.10)
==249724==    by 0x63082B: ??? (in /usr/bin/python3.10)
==249724==    by 0x6BF551: Py_InitializeFromConfig (in /usr/bin/python3.10)
==249724==    by 0x704415: ??? (in /usr/bin/python3.10)
==249724==    by 0x704470: ??? (in /usr/bin/python3.10)
==249724==    by 0x7044BC: Py_BytesMain (in /usr/bin/python3.10)
==249724== 
==249724== 576 bytes in 1 blocks are still reachable in loss record 12 of 99
==249724==    at 0x4848899: malloc (in /usr/libexec/valgrind/vgpreload_memcheck-amd64-linux.so)
==249724==    by 0x5F2EB0: PyObject_Malloc (in /usr/bin/python3.10)
==249724==    by 0x60211C: ??? (in /usr/bin/python3.10)
==249724==    by 0x5FF185: PyDict_SetDefault (in /usr/bin/python3.10)
==249724==    by 0x5DA11C: PyType_Ready (in /usr/bin/python3.10)
==249724==    by 0x6F1E87: ??? (in /usr/bin/python3.10)
==249724==    by 0x6C3B38: ??? (in /usr/bin/python3.10)
==249724==    by 0x63082B: ??? (in /usr/bin/python3.10)
==249724==    by 0x6BF551: Py_InitializeFromConfig (in /usr/bin/python3.10)
==249724==    by 0x704415: ??? (in /usr/bin/python3.10)
==249724==    by 0x704470: ??? (in /usr/bin/python3.10)
==249724==    by 0x7044BC: Py_BytesMain (in /usr/bin/python3.10)
==249724== 
==249724== 576 bytes in 1 blocks are still reachable in loss record 13 of 99
==249724==    at 0x4848899: malloc (in /usr/libexec/valgrind/vgpreload_memcheck-amd64-linux.so)
==249724==    by 0x5F2EB0: PyObject_Malloc (in /usr/bin/python3.10)
==249724==    by 0x60211C: ??? (in /usr/bin/python3.10)
==249724==    by 0x5FF185: PyDict_SetDefault (in /usr/bin/python3.10)
==249724==    by 0x5DADF5: PyType_Ready (in /usr/bin/python3.10)
==249724==    by 0x6F1F95: ??? (in /usr/bin/python3.10)
==249724==    by 0x6C3B38: ??? (in /usr/bin/python3.10)
==249724==    by 0x63082B: ??? (in /usr/bin/python3.10)
==249724==    by 0x6BF551: Py_InitializeFromConfig (in /usr/bin/python3.10)
==249724==    by 0x704415: ??? (in /usr/bin/python3.10)
==249724==    by 0x704470: ??? (in /usr/bin/python3.10)
==249724==    by 0x7044BC: Py_BytesMain (in /usr/bin/python3.10)
==249724== 
==249724== 576 bytes in 1 blocks are still reachable in loss record 14 of 99
==249724==    at 0x4848899: malloc (in /usr/libexec/valgrind/vgpreload_memcheck-amd64-linux.so)
==249724==    by 0x5F2EB0: PyObject_Malloc (in /usr/bin/python3.10)
==249724==    by 0x60211C: ??? (in /usr/bin/python3.10)
==249724==    by 0x5FF185: PyDict_SetDefault (in /usr/bin/python3.10)
==249724==    by 0x5DA11C: PyType_Ready (in /usr/bin/python3.10)
==249724==    by 0x6F1FB9: ??? (in /usr/bin/python3.10)
==249724==    by 0x6C3B38: ??? (in /usr/bin/python3.10)
==249724==    by 0x63082B: ??? (in /usr/bin/python3.10)
==249724==    by 0x6BF551: Py_InitializeFromConfig (in /usr/bin/python3.10)
==249724==    by 0x704415: ??? (in /usr/bin/python3.10)
==249724==    by 0x704470: ??? (in /usr/bin/python3.10)
==249724==    by 0x7044BC: Py_BytesMain (in /usr/bin/python3.10)
==249724== 
==249724== 576 bytes in 1 blocks are still reachable in loss record 15 of 99
==249724==    at 0x4848899: malloc (in /usr/libexec/valgrind/vgpreload_memcheck-amd64-linux.so)
==249724==    by 0x5F2EB0: PyObject_Malloc (in /usr/bin/python3.10)
==249724==    by 0x60211C: ??? (in /usr/bin/python3.10)
==249724==    by 0x5FF185: PyDict_SetDefault (in /usr/bin/python3.10)
==249724==    by 0x5DA11C: PyType_Ready (in /usr/bin/python3.10)
==249724==    by 0x6F1FCB: ??? (in /usr/bin/python3.10)
==249724==    by 0x6C3B38: ??? (in /usr/bin/python3.10)
==249724==    by 0x63082B: ??? (in /usr/bin/python3.10)
==249724==    by 0x6BF551: Py_InitializeFromConfig (in /usr/bin/python3.10)
==249724==    by 0x704415: ??? (in /usr/bin/python3.10)
==249724==    by 0x704470: ??? (in /usr/bin/python3.10)
==249724==    by 0x7044BC: Py_BytesMain (in /usr/bin/python3.10)
==249724== 
==249724== 576 bytes in 1 blocks are still reachable in loss record 16 of 99
==249724==    at 0x4848899: malloc (in /usr/libexec/valgrind/vgpreload_memcheck-amd64-linux.so)
==249724==    by 0x5F2EB0: PyObject_Malloc (in /usr/bin/python3.10)
==249724==    by 0x60211C: ??? (in /usr/bin/python3.10)
==249724==    by 0x603263: PyDict_SetItem (in /usr/bin/python3.10)
==249724==    by 0x5DA030: PyType_Ready (in /usr/bin/python3.10)
==249724==    by 0x6F1FEF: ??? (in /usr/bin/python3.10)
==249724==    by 0x6C3B38: ??? (in /usr/bin/python3.10)
==249724==    by 0x63082B: ??? (in /usr/bin/python3.10)
==249724==    by 0x6BF551: Py_InitializeFromConfig (in /usr/bin/python3.10)
==249724==    by 0x704415: ??? (in /usr/bin/python3.10)
==249724==    by 0x704470: ??? (in /usr/bin/python3.10)
==249724==    by 0x7044BC: Py_BytesMain (in /usr/bin/python3.10)
==249724== 
==249724== 576 bytes in 1 blocks are still reachable in loss record 17 of 99
==249724==    at 0x4848899: malloc (in /usr/libexec/valgrind/vgpreload_memcheck-amd64-linux.so)
==249724==    by 0x5F2EB0: PyObject_Malloc (in /usr/bin/python3.10)
==249724==    by 0x60211C: ??? (in /usr/bin/python3.10)
==249724==    by 0x603263: PyDict_SetItem (in /usr/bin/python3.10)
==249724==    by 0x5DA030: PyType_Ready (in /usr/bin/python3.10)
==249724==    by 0x6F2091: ??? (in /usr/bin/python3.10)
==249724==    by 0x6C3B38: ??? (in /usr/bin/python3.10)
==249724==    by 0x63082B: ??? (in /usr/bin/python3.10)
==249724==    by 0x6BF551: Py_InitializeFromConfig (in /usr/bin/python3.10)
==249724==    by 0x704415: ??? (in /usr/bin/python3.10)
==249724==    by 0x704470: ??? (in /usr/bin/python3.10)
==249724==    by 0x7044BC: Py_BytesMain (in /usr/bin/python3.10)
==249724== 
==249724== 576 bytes in 1 blocks are still reachable in loss record 18 of 99
==249724==    at 0x4848899: malloc (in /usr/libexec/valgrind/vgpreload_memcheck-amd64-linux.so)
==249724==    by 0x5F2EB0: PyObject_Malloc (in /usr/bin/python3.10)
==249724==    by 0x60211C: ??? (in /usr/bin/python3.10)
==249724==    by 0x5FF185: PyDict_SetDefault (in /usr/bin/python3.10)
==249724==    by 0x5DADF5: PyType_Ready (in /usr/bin/python3.10)
==249724==    by 0x6F2133: ??? (in /usr/bin/python3.10)
==249724==    by 0x6C3B38: ??? (in /usr/bin/python3.10)
==249724==    by 0x63082B: ??? (in /usr/bin/python3.10)
==249724==    by 0x6BF551: Py_InitializeFromConfig (in /usr/bin/python3.10)
==249724==    by 0x704415: ??? (in /usr/bin/python3.10)
==249724==    by 0x704470: ??? (in /usr/bin/python3.10)
==249724==    by 0x7044BC: Py_BytesMain (in /usr/bin/python3.10)
==249724== 
==249724== 576 bytes in 1 blocks are still reachable in loss record 19 of 99
==249724==    at 0x4848899: malloc (in /usr/libexec/valgrind/vgpreload_memcheck-amd64-linux.so)
==249724==    by 0x5F2EB0: PyObject_Malloc (in /usr/bin/python3.10)
==249724==    by 0x60211C: ??? (in /usr/bin/python3.10)
==249724==    by 0x603263: PyDict_SetItem (in /usr/bin/python3.10)
==249724==    by 0x5DA222: PyType_Ready (in /usr/bin/python3.10)
==249724==    by 0x6F217B: ??? (in /usr/bin/python3.10)
==249724==    by 0x6C3B38: ??? (in /usr/bin/python3.10)
==249724==    by 0x63082B: ??? (in /usr/bin/python3.10)
==249724==    by 0x6BF551: Py_InitializeFromConfig (in /usr/bin/python3.10)
==249724==    by 0x704415: ??? (in /usr/bin/python3.10)
==249724==    by 0x704470: ??? (in /usr/bin/python3.10)
==249724==    by 0x7044BC: Py_BytesMain (in /usr/bin/python3.10)
==249724== 
==249724== 576 bytes in 1 blocks are still reachable in loss record 20 of 99
==249724==    at 0x4848899: malloc (in /usr/libexec/valgrind/vgpreload_memcheck-amd64-linux.so)
==249724==    by 0x5F2EB0: PyObject_Malloc (in /usr/bin/python3.10)
==249724==    by 0x60211C: ??? (in /usr/bin/python3.10)
==249724==    by 0x5FF185: PyDict_SetDefault (in /usr/bin/python3.10)
==249724==    by 0x5DA17B: PyType_Ready (in /usr/bin/python3.10)
==249724==    by 0x6F21C3: ??? (in /usr/bin/python3.10)
==249724==    by 0x6C3B38: ??? (in /usr/bin/python3.10)
==249724==    by 0x63082B: ??? (in /usr/bin/python3.10)
==249724==    by 0x6BF551: Py_InitializeFromConfig (in /usr/bin/python3.10)
==249724==    by 0x704415: ??? (in /usr/bin/python3.10)
==249724==    by 0x704470: ??? (in /usr/bin/python3.10)
==249724==    by 0x7044BC: Py_BytesMain (in /usr/bin/python3.10)
==249724== 
==249724== 576 bytes in 1 blocks are still reachable in loss record 21 of 99
==249724==    at 0x4848899: malloc (in /usr/libexec/valgrind/vgpreload_memcheck-amd64-linux.so)
==249724==    by 0x5F2EB0: PyObject_Malloc (in /usr/bin/python3.10)
==249724==    by 0x60211C: ??? (in /usr/bin/python3.10)
==249724==    by 0x603263: PyDict_SetItem (in /usr/bin/python3.10)
==249724==    by 0x5DA222: PyType_Ready (in /usr/bin/python3.10)
==249724==    by 0x6F21E7: ??? (in /usr/bin/python3.10)
==249724==    by 0x6C3B38: ??? (in /usr/bin/python3.10)
==249724==    by 0x63082B: ??? (in /usr/bin/python3.10)
==249724==    by 0x6BF551: Py_InitializeFromConfig (in /usr/bin/python3.10)
==249724==    by 0x704415: ??? (in /usr/bin/python3.10)
==249724==    by 0x704470: ??? (in /usr/bin/python3.10)
==249724==    by 0x7044BC: Py_BytesMain (in /usr/bin/python3.10)
==249724== 
==249724== 576 bytes in 1 blocks are still reachable in loss record 22 of 99
==249724==    at 0x4848899: malloc (in /usr/libexec/valgrind/vgpreload_memcheck-amd64-linux.so)
==249724==    by 0x5F2EB0: PyObject_Malloc (in /usr/bin/python3.10)
==249724==    by 0x60211C: ??? (in /usr/bin/python3.10)
==249724==    by 0x603263: PyDict_SetItem (in /usr/bin/python3.10)
==249724==    by 0x5DA030: PyType_Ready (in /usr/bin/python3.10)
==249724==    by 0x6F22E3: ??? (in /usr/bin/python3.10)
==249724==    by 0x6C3B38: ??? (in /usr/bin/python3.10)
==249724==    by 0x63082B: ??? (in /usr/bin/python3.10)
==249724==    by 0x6BF551: Py_InitializeFromConfig (in /usr/bin/python3.10)
==249724==    by 0x704415: ??? (in /usr/bin/python3.10)
==249724==    by 0x704470: ??? (in /usr/bin/python3.10)
==249724==    by 0x7044BC: Py_BytesMain (in /usr/bin/python3.10)
==249724== 
==249724== 576 bytes in 1 blocks are still reachable in loss record 23 of 99
==249724==    at 0x4848899: malloc (in /usr/libexec/valgrind/vgpreload_memcheck-amd64-linux.so)
==249724==    by 0x5F2EB0: PyObject_Malloc (in /usr/bin/python3.10)
==249724==    by 0x60211C: ??? (in /usr/bin/python3.10)
==249724==    by 0x5FF185: PyDict_SetDefault (in /usr/bin/python3.10)
==249724==    by 0x5DA17B: PyType_Ready (in /usr/bin/python3.10)
==249724==    by 0x6F2307: ??? (in /usr/bin/python3.10)
==249724==    by 0x6C3B38: ??? (in /usr/bin/python3.10)
==249724==    by 0x63082B: ??? (in /usr/bin/python3.10)
==249724==    by 0x6BF551: Py_InitializeFromConfig (in /usr/bin/python3.10)
==249724==    by 0x704415: ??? (in /usr/bin/python3.10)
==249724==    by 0x704470: ??? (in /usr/bin/python3.10)
==249724==    by 0x7044BC: Py_BytesMain (in /usr/bin/python3.10)
==249724== 
==249724== 576 bytes in 1 blocks are still reachable in loss record 24 of 99
==249724==    at 0x4848899: malloc (in /usr/libexec/valgrind/vgpreload_memcheck-amd64-linux.so)
==249724==    by 0x5F2EB0: PyObject_Malloc (in /usr/bin/python3.10)
==249724==    by 0x60211C: ??? (in /usr/bin/python3.10)
==249724==    by 0x603263: PyDict_SetItem (in /usr/bin/python3.10)
==249724==    by 0x5DA030: PyType_Ready (in /usr/bin/python3.10)
==249724==    by 0x6F2319: ??? (in /usr/bin/python3.10)
==249724==    by 0x6C3B38: ??? (in /usr/bin/python3.10)
==249724==    by 0x63082B: ??? (in /usr/bin/python3.10)
==249724==    by 0x6BF551: Py_InitializeFromConfig (in /usr/bin/python3.10)
==249724==    by 0x704415: ??? (in /usr/bin/python3.10)
==249724==    by 0x704470: ??? (in /usr/bin/python3.10)
==249724==    by 0x7044BC: Py_BytesMain (in /usr/bin/python3.10)
==249724== 
==249724== 576 bytes in 1 blocks are still reachable in loss record 25 of 99
==249724==    at 0x4848899: malloc (in /usr/libexec/valgrind/vgpreload_memcheck-amd64-linux.so)
==249724==    by 0x5F2EB0: PyObject_Malloc (in /usr/bin/python3.10)
==249724==    by 0x60211C: ??? (in /usr/bin/python3.10)
==249724==    by 0x603263: PyDict_SetItem (in /usr/bin/python3.10)
==249724==    by 0x5DA030: PyType_Ready (in /usr/bin/python3.10)
==249724==    by 0x6F2373: ??? (in /usr/bin/python3.10)
==249724==    by 0x6C3B38: ??? (in /usr/bin/python3.10)
==249724==    by 0x63082B: ??? (in /usr/bin/python3.10)
==249724==    by 0x6BF551: Py_InitializeFromConfig (in /usr/bin/python3.10)
==249724==    by 0x704415: ??? (in /usr/bin/python3.10)
==249724==    by 0x704470: ??? (in /usr/bin/python3.10)
==249724==    by 0x7044BC: Py_BytesMain (in /usr/bin/python3.10)
==249724== 
==249724== 576 bytes in 1 blocks are still reachable in loss record 26 of 99
==249724==    at 0x4848899: malloc (in /usr/libexec/valgrind/vgpreload_memcheck-amd64-linux.so)
==249724==    by 0x5F2EB0: PyObject_Malloc (in /usr/bin/python3.10)
==249724==    by 0x60211C: ??? (in /usr/bin/python3.10)
==249724==    by 0x603263: PyDict_SetItem (in /usr/bin/python3.10)
==249724==    by 0x5DA030: PyType_Ready (in /usr/bin/python3.10)
==249724==    by 0x6F2385: ??? (in /usr/bin/python3.10)
==249724==    by 0x6C3B38: ??? (in /usr/bin/python3.10)
==249724==    by 0x63082B: ??? (in /usr/bin/python3.10)
==249724==    by 0x6BF551: Py_InitializeFromConfig (in /usr/bin/python3.10)
==249724==    by 0x704415: ??? (in /usr/bin/python3.10)
==249724==    by 0x704470: ??? (in /usr/bin/python3.10)
==249724==    by 0x7044BC: Py_BytesMain (in /usr/bin/python3.10)
==249724== 
==249724== 576 bytes in 1 blocks are still reachable in loss record 27 of 99
==249724==    at 0x4848899: malloc (in /usr/libexec/valgrind/vgpreload_memcheck-amd64-linux.so)
==249724==    by 0x5F2EB0: PyObject_Malloc (in /usr/bin/python3.10)
==249724==    by 0x60211C: ??? (in /usr/bin/python3.10)
==249724==    by 0x603263: PyDict_SetItem (in /usr/bin/python3.10)
==249724==    by 0x5FED10: PyDict_SetItemString (in /usr/bin/python3.10)
==249724==    by 0x6EE37C: ??? (in /usr/bin/python3.10)
==249724==    by 0x6EE578: _PyStructSequence_InitType (in /usr/bin/python3.10)
==249724==    by 0x6C3B5D: ??? (in /usr/bin/python3.10)
==249724==    by 0x63082B: ??? (in /usr/bin/python3.10)
==249724==    by 0x6BF551: Py_InitializeFromConfig (in /usr/bin/python3.10)
==249724==    by 0x704415: ??? (in /usr/bin/python3.10)
==249724==    by 0x704470: ??? (in /usr/bin/python3.10)
==249724== 
==249724== 576 bytes in 1 blocks are still reachable in loss record 28 of 99
==249724==    at 0x4848899: malloc (in /usr/libexec/valgrind/vgpreload_memcheck-amd64-linux.so)
==249724==    by 0x5F2EB0: PyObject_Malloc (in /usr/bin/python3.10)
==249724==    by 0x60211C: ??? (in /usr/bin/python3.10)
==249724==    by 0x5FF185: PyDict_SetDefault (in /usr/bin/python3.10)
==249724==    by 0x5DADF5: PyType_Ready (in /usr/bin/python3.10)
==249724==    by 0x6EE552: _PyStructSequence_InitType (in /usr/bin/python3.10)
==249724==    by 0x6C3BC6: ??? (in /usr/bin/python3.10)
==249724==    by 0x63082B: ??? (in /usr/bin/python3.10)
==249724==    by 0x6BF551: Py_InitializeFromConfig (in /usr/bin/python3.10)
==249724==    by 0x704415: ??? (in /usr/bin/python3.10)
==249724==    by 0x704470: ??? (in /usr/bin/python3.10)
==249724==    by 0x7044BC: Py_BytesMain (in /usr/bin/python3.10)
==249724== 
==249724== 576 bytes in 1 blocks are still reachable in loss record 29 of 99
==249724==    at 0x4848899: malloc (in /usr/libexec/valgrind/vgpreload_memcheck-amd64-linux.so)
==249724==    by 0x5F2EB0: PyObject_Malloc (in /usr/bin/python3.10)
==249724==    by 0x60211C: ??? (in /usr/bin/python3.10)
==249724==    by 0x5FF185: PyDict_SetDefault (in /usr/bin/python3.10)
==249724==    by 0x5DADF5: PyType_Ready (in /usr/bin/python3.10)
==249724==    by 0x6FE808: ??? (in /usr/bin/python3.10)
==249724==    by 0x6C3BDB: ??? (in /usr/bin/python3.10)
==249724==    by 0x63082B: ??? (in /usr/bin/python3.10)
==249724==    by 0x6BF551: Py_InitializeFromConfig (in /usr/bin/python3.10)
==249724==    by 0x704415: ??? (in /usr/bin/python3.10)
==249724==    by 0x704470: ??? (in /usr/bin/python3.10)
==249724==    by 0x7044BC: Py_BytesMain (in /usr/bin/python3.10)
==249724== 
==249724== 576 bytes in 1 blocks are still reachable in loss record 30 of 99
==249724==    at 0x4848899: malloc (in /usr/libexec/valgrind/vgpreload_memcheck-amd64-linux.so)
==249724==    by 0x5F2EB0: PyObject_Malloc (in /usr/bin/python3.10)
==249724==    by 0x60211C: ??? (in /usr/bin/python3.10)
==249724==    by 0x603263: PyDict_SetItem (in /usr/bin/python3.10)
==249724==    by 0x5DAF3C: PyType_Ready (in /usr/bin/python3.10)
==249724==    by 0x6FEAB5: ??? (in /usr/bin/python3.10)
==249724==    by 0x6C3BDB: ??? (in /usr/bin/python3.10)
==249724==    by 0x63082B: ??? (in /usr/bin/python3.10)
==249724==    by 0x6BF551: Py_InitializeFromConfig (in /usr/bin/python3.10)
==249724==    by 0x704415: ??? (in /usr/bin/python3.10)
==249724==    by 0x704470: ??? (in /usr/bin/python3.10)
==249724==    by 0x7044BC: Py_BytesMain (in /usr/bin/python3.10)
==249724== 
==249724== 576 bytes in 1 blocks are still reachable in loss record 31 of 99
==249724==    at 0x4848899: malloc (in /usr/libexec/valgrind/vgpreload_memcheck-amd64-linux.so)
==249724==    by 0x5F2EB0: PyObject_Malloc (in /usr/bin/python3.10)
==249724==    by 0x60211C: ??? (in /usr/bin/python3.10)
==249724==    by 0x603263: PyDict_SetItem (in /usr/bin/python3.10)
==249724==    by 0x6E760E: ??? (in /usr/bin/python3.10)
==249724==    by 0x5DA6C6: PyType_Ready (in /usr/bin/python3.10)
==249724==    by 0x6FEF52: ??? (in /usr/bin/python3.10)
==249724==    by 0x6C3BDB: ??? (in /usr/bin/python3.10)
==249724==    by 0x63082B: ??? (in /usr/bin/python3.10)
==249724==    by 0x6BF551: Py_InitializeFromConfig (in /usr/bin/python3.10)
==249724==    by 0x704415: ??? (in /usr/bin/python3.10)
==249724==    by 0x704470: ??? (in /usr/bin/python3.10)
==249724== 
==249724== 576 bytes in 1 blocks are still reachable in loss record 32 of 99
==249724==    at 0x4848899: malloc (in /usr/libexec/valgrind/vgpreload_memcheck-amd64-linux.so)
==249724==    by 0x5F2EB0: PyObject_Malloc (in /usr/bin/python3.10)
==249724==    by 0x60211C: ??? (in /usr/bin/python3.10)
==249724==    by 0x603263: PyDict_SetItem (in /usr/bin/python3.10)
==249724==    by 0x6E760E: ??? (in /usr/bin/python3.10)
==249724==    by 0x5DA6C6: PyType_Ready (in /usr/bin/python3.10)
==249724==    by 0x6FF18D: ??? (in /usr/bin/python3.10)
==249724==    by 0x6C3BDB: ??? (in /usr/bin/python3.10)
==249724==    by 0x63082B: ??? (in /usr/bin/python3.10)
==249724==    by 0x6BF551: Py_InitializeFromConfig (in /usr/bin/python3.10)
==249724==    by 0x704415: ??? (in /usr/bin/python3.10)
==249724==    by 0x704470: ??? (in /usr/bin/python3.10)
==249724== 
==249724== 576 bytes in 1 blocks are still reachable in loss record 33 of 99
==249724==    at 0x4848899: malloc (in /usr/libexec/valgrind/vgpreload_memcheck-amd64-linux.so)
==249724==    by 0x5F2EB0: PyObject_Malloc (in /usr/bin/python3.10)
==249724==    by 0x60211C: ??? (in /usr/bin/python3.10)
==249724==    by 0x603263: PyDict_SetItem (in /usr/bin/python3.10)
==249724==    by 0x5FED10: PyDict_SetItemString (in /usr/bin/python3.10)
==249724==    by 0x6EE346: ??? (in /usr/bin/python3.10)
==249724==    by 0x6EE578: _PyStructSequence_InitType (in /usr/bin/python3.10)
==249724==    by 0x6C3C00: ??? (in /usr/bin/python3.10)
==249724==    by 0x63082B: ??? (in /usr/bin/python3.10)
==249724==    by 0x6BF551: Py_InitializeFromConfig (in /usr/bin/python3.10)
==249724==    by 0x704415: ??? (in /usr/bin/python3.10)
==249724==    by 0x704470: ??? (in /usr/bin/python3.10)
==249724== 
==249724== 576 bytes in 1 blocks are still reachable in loss record 34 of 99
==249724==    at 0x4848899: malloc (in /usr/libexec/valgrind/vgpreload_memcheck-amd64-linux.so)
==249724==    by 0x5F2EB0: PyObject_Malloc (in /usr/bin/python3.10)
==249724==    by 0x60211C: ??? (in /usr/bin/python3.10)
==249724==    by 0x603263: PyDict_SetItem (in /usr/bin/python3.10)
==249724==    by 0x5DA030: PyType_Ready (in /usr/bin/python3.10)
==249724==    by 0x6C3C1B: ??? (in /usr/bin/python3.10)
==249724==    by 0x63082B: ??? (in /usr/bin/python3.10)
==249724==    by 0x6BF551: Py_InitializeFromConfig (in /usr/bin/python3.10)
==249724==    by 0x704415: ??? (in /usr/bin/python3.10)
==249724==    by 0x704470: ??? (in /usr/bin/python3.10)
==249724==    by 0x7044BC: Py_BytesMain (in /usr/bin/python3.10)
==249724==    by 0x489DD8F: (below main) (libc_start_call_main.h:58)
==249724== 
==249724== 576 bytes in 1 blocks are still reachable in loss record 35 of 99
==249724==    at 0x4848899: malloc (in /usr/libexec/valgrind/vgpreload_memcheck-amd64-linux.so)
==249724==    by 0x5F2EB0: PyObject_Malloc (in /usr/bin/python3.10)
==249724==    by 0x60211C: ??? (in /usr/bin/python3.10)
==249724==    by 0x603263: PyDict_SetItem (in /usr/bin/python3.10)
==249724==    by 0x5DA030: PyType_Ready (in /usr/bin/python3.10)
==249724==    by 0x6C3C99: ??? (in /usr/bin/python3.10)
==249724==    by 0x63082B: ??? (in /usr/bin/python3.10)
==249724==    by 0x6BF551: Py_InitializeFromConfig (in /usr/bin/python3.10)
==249724==    by 0x704415: ??? (in /usr/bin/python3.10)
==249724==    by 0x704470: ??? (in /usr/bin/python3.10)
==249724==    by 0x7044BC: Py_BytesMain (in /usr/bin/python3.10)
==249724==    by 0x489DD8F: (below main) (libc_start_call_main.h:58)
==249724== 
==249724== 576 bytes in 1 blocks are still reachable in loss record 36 of 99
==249724==    at 0x4848899: malloc (in /usr/libexec/valgrind/vgpreload_memcheck-amd64-linux.so)
==249724==    by 0x5F2EB0: PyObject_Malloc (in /usr/bin/python3.10)
==249724==    by 0x60211C: ??? (in /usr/bin/python3.10)
==249724==    by 0x5FF185: PyDict_SetDefault (in /usr/bin/python3.10)
==249724==    by 0x5DADF5: PyType_Ready (in /usr/bin/python3.10)
==249724==    by 0x6EE552: _PyStructSequence_InitType (in /usr/bin/python3.10)
==249724==    by 0x6C428E: ??? (in /usr/bin/python3.10)
==249724==    by 0x63082B: ??? (in /usr/bin/python3.10)
==249724==    by 0x6BF551: Py_InitializeFromConfig (in /usr/bin/python3.10)
==249724==    by 0x704415: ??? (in /usr/bin/python3.10)
==249724==    by 0x704470: ??? (in /usr/bin/python3.10)
==249724==    by 0x7044BC: Py_BytesMain (in /usr/bin/python3.10)
==249724== 
==249724== 576 bytes in 1 blocks are still reachable in loss record 37 of 99
==249724==    at 0x4848899: malloc (in /usr/libexec/valgrind/vgpreload_memcheck-amd64-linux.so)
==249724==    by 0x5F2EB0: PyObject_Malloc (in /usr/bin/python3.10)
==249724==    by 0x60211C: ??? (in /usr/bin/python3.10)
==249724==    by 0x603263: PyDict_SetItem (in /usr/bin/python3.10)
==249724==    by 0x5FED10: PyDict_SetItemString (in /usr/bin/python3.10)
==249724==    by 0x6EE37C: ??? (in /usr/bin/python3.10)
==249724==    by 0x6EE578: _PyStructSequence_InitType (in /usr/bin/python3.10)
==249724==    by 0x6C4576: ??? (in /usr/bin/python3.10)
==249724==    by 0x63082B: ??? (in /usr/bin/python3.10)
==249724==    by 0x6BF551: Py_InitializeFromConfig (in /usr/bin/python3.10)
==249724==    by 0x704415: ??? (in /usr/bin/python3.10)
==249724==    by 0x704470: ??? (in /usr/bin/python3.10)
==249724== 
==249724== 576 bytes in 1 blocks are still reachable in loss record 38 of 99
==249724==    at 0x4848899: malloc (in /usr/libexec/valgrind/vgpreload_memcheck-amd64-linux.so)
==249724==    by 0x5F2EB0: PyObject_Malloc (in /usr/bin/python3.10)
==249724==    by 0x60211C: ??? (in /usr/bin/python3.10)
==249724==    by 0x603263: PyDict_SetItem (in /usr/bin/python3.10)
==249724==    by 0x5FED10: PyDict_SetItemString (in /usr/bin/python3.10)
==249724==    by 0x6EE419: ??? (in /usr/bin/python3.10)
==249724==    by 0x6EE578: _PyStructSequence_InitType (in /usr/bin/python3.10)
==249724==    by 0x6B5F64: PyThread_GetInfo (in /usr/bin/python3.10)
==249724==    by 0x6C482C: ??? (in /usr/bin/python3.10)
==249724==    by 0x63082B: ??? (in /usr/bin/python3.10)
==249724==    by 0x6BF551: Py_InitializeFromConfig (in /usr/bin/python3.10)
==249724==    by 0x704415: ??? (in /usr/bin/python3.10)
==249724== 
==249724== 576 bytes in 1 blocks are still reachable in loss record 39 of 99
==249724==    at 0x4848899: malloc (in /usr/libexec/valgrind/vgpreload_memcheck-amd64-linux.so)
==249724==    by 0x5F2EB0: PyObject_Malloc (in /usr/bin/python3.10)
==249724==    by 0x60211C: ??? (in /usr/bin/python3.10)
==249724==    by 0x603263: PyDict_SetItem (in /usr/bin/python3.10)
==249724==    by 0x5FED10: PyDict_SetItemString (in /usr/bin/python3.10)
==249724==    by 0x6EE37C: ??? (in /usr/bin/python3.10)
==249724==    by 0x6EE578: _PyStructSequence_InitType (in /usr/bin/python3.10)
==249724==    by 0x68CFBF: ??? (in /usr/bin/python3.10)
==249724==    by 0x6F2D02: PyModule_ExecDef (in /usr/bin/python3.10)
==249724==    by 0x6C996F: ??? (in /usr/bin/python3.10)
==249724==    by 0x53B136: ??? (in /usr/bin/python3.10)
==249724==    by 0x628A39: PyObject_Call (in /usr/bin/python3.10)
==249724== 
==249724== 576 bytes in 1 blocks are still reachable in loss record 40 of 99
==249724==    at 0x4848899: malloc (in /usr/libexec/valgrind/vgpreload_memcheck-amd64-linux.so)
==249724==    by 0x5F2EB0: PyObject_Malloc (in /usr/bin/python3.10)
==249724==    by 0x60211C: ??? (in /usr/bin/python3.10)
==249724==    by 0x5FF185: PyDict_SetDefault (in /usr/bin/python3.10)
==249724==    by 0x5DA17B: PyType_Ready (in /usr/bin/python3.10)
==249724==    by 0x6C37B6: PyModule_AddType (in /usr/bin/python3.10)
==249724==    by 0x69D3B4: PyInit__io (in /usr/bin/python3.10)
==249724==    by 0x6CA547: ??? (in /usr/bin/python3.10)
==249724==    by 0x6CA60D: ??? (in /usr/bin/python3.10)
==249724==    by 0x53B136: ??? (in /usr/bin/python3.10)
==249724==    by 0x628A39: PyObject_Call (in /usr/bin/python3.10)
==249724==    by 0x5AFA8D: _PyEval_EvalFrameDefault (in /usr/bin/python3.10)
==249724== 
==249724== 576 bytes in 1 blocks are still reachable in loss record 41 of 99
==249724==    at 0x4848899: malloc (in /usr/libexec/valgrind/vgpreload_memcheck-amd64-linux.so)
==249724==    by 0x5F2EB0: PyObject_Malloc (in /usr/bin/python3.10)
==249724==    by 0x60211C: ??? (in /usr/bin/python3.10)
==249724==    by 0x5FF185: PyDict_SetDefault (in /usr/bin/python3.10)
==249724==    by 0x5DA17B: PyType_Ready (in /usr/bin/python3.10)
==249724==    by 0x6C37B6: PyModule_AddType (in /usr/bin/python3.10)
==249724==    by 0x69D414: PyInit__io (in /usr/bin/python3.10)
==249724==    by 0x6CA547: ??? (in /usr/bin/python3.10)
==249724==    by 0x6CA60D: ??? (in /usr/bin/python3.10)
==249724==    by 0x53B136: ??? (in /usr/bin/python3.10)
==249724==    by 0x628A39: PyObject_Call (in /usr/bin/python3.10)
==249724==    by 0x5AFA8D: _PyEval_EvalFrameDefault (in /usr/bin/python3.10)
==249724== 
==249724== 576 bytes in 1 blocks are still reachable in loss record 42 of 99
==249724==    at 0x4848899: malloc (in /usr/libexec/valgrind/vgpreload_memcheck-amd64-linux.so)
==249724==    by 0x5F2EB0: PyObject_Malloc (in /usr/bin/python3.10)
==249724==    by 0x60211C: ??? (in /usr/bin/python3.10)
==249724==    by 0x5FF185: PyDict_SetDefault (in /usr/bin/python3.10)
==249724==    by 0x5DADF5: PyType_Ready (in /usr/bin/python3.10)
==249724==    by 0x6EE552: _PyStructSequence_InitType (in /usr/bin/python3.10)
==249724==    by 0x65F08F: ??? (in /usr/bin/python3.10)
==249724==    by 0x6F2D02: PyModule_ExecDef (in /usr/bin/python3.10)
==249724==    by 0x6C996F: ??? (in /usr/bin/python3.10)
==249724==    by 0x53B136: ??? (in /usr/bin/python3.10)
==249724==    by 0x628A39: PyObject_Call (in /usr/bin/python3.10)
==249724==    by 0x5AFA8D: _PyEval_EvalFrameDefault (in /usr/bin/python3.10)
==249724== 
==249724== 576 bytes in 1 blocks are still reachable in loss record 43 of 99
==249724==    at 0x4848899: malloc (in /usr/libexec/valgrind/vgpreload_memcheck-amd64-linux.so)
==249724==    by 0x5F2EB0: PyObject_Malloc (in /usr/bin/python3.10)
==249724==    by 0x60211C: ??? (in /usr/bin/python3.10)
==249724==    by 0x603263: PyDict_SetItem (in /usr/bin/python3.10)
==249724==    by 0x5DAF3C: PyType_Ready (in /usr/bin/python3.10)
==249724==    by 0x6EE552: _PyStructSequence_InitType (in /usr/bin/python3.10)
==249724==    by 0x6C321D: ??? (in /usr/bin/python3.10)
==249724==    by 0x6BBA2F: ??? (in /usr/bin/python3.10)
==249724==    by 0x6BF578: Py_InitializeFromConfig (in /usr/bin/python3.10)
==249724==    by 0x704415: ??? (in /usr/bin/python3.10)
==249724==    by 0x704470: ??? (in /usr/bin/python3.10)
==249724==    by 0x7044BC: Py_BytesMain (in /usr/bin/python3.10)
==249724== 
==249724== 576 bytes in 1 blocks are still reachable in loss record 44 of 99
==249724==    at 0x4848899: malloc (in /usr/libexec/valgrind/vgpreload_memcheck-amd64-linux.so)
==249724==    by 0x5F2EB0: PyObject_Malloc (in /usr/bin/python3.10)
==249724==    by 0x60211C: ??? (in /usr/bin/python3.10)
==249724==    by 0x5FF185: PyDict_SetDefault (in /usr/bin/python3.10)
==249724==    by 0x5DADF5: PyType_Ready (in /usr/bin/python3.10)
==249724==    by 0x6C37B6: PyModule_AddType (in /usr/bin/python3.10)
==249724==    by 0x6AD066: ??? (in /usr/bin/python3.10)
==249724==    by 0x6F2D02: PyModule_ExecDef (in /usr/bin/python3.10)
==249724==    by 0x6C996F: ??? (in /usr/bin/python3.10)
==249724==    by 0x53B136: ??? (in /usr/bin/python3.10)
==249724==    by 0x628A39: PyObject_Call (in /usr/bin/python3.10)
==249724==    by 0x5AFA8D: _PyEval_EvalFrameDefault (in /usr/bin/python3.10)
==249724== 
==249724== 645 bytes in 1 blocks are still reachable in loss record 45 of 99
==249724==    at 0x4848899: malloc (in /usr/libexec/valgrind/vgpreload_memcheck-amd64-linux.so)
==249724==    by 0x5C7F61: PyUnicode_FromString (in /usr/bin/python3.10)
==249724==    by 0x5DAF1C: PyType_Ready (in /usr/bin/python3.10)
==249724==    by 0x6F21D5: ??? (in /usr/bin/python3.10)
==249724==    by 0x6C3B38: ??? (in /usr/bin/python3.10)
==249724==    by 0x63082B: ??? (in /usr/bin/python3.10)
==249724==    by 0x6BF551: Py_InitializeFromConfig (in /usr/bin/python3.10)
==249724==    by 0x704415: ??? (in /usr/bin/python3.10)
==249724==    by 0x704470: ??? (in /usr/bin/python3.10)
==249724==    by 0x7044BC: Py_BytesMain (in /usr/bin/python3.10)
==249724==    by 0x489DD8F: (below main) (libc_start_call_main.h:58)
==249724== 
==249724== 654 bytes in 1 blocks are still reachable in loss record 46 of 99
==249724==    at 0x4848899: malloc (in /usr/libexec/valgrind/vgpreload_memcheck-amd64-linux.so)
==249724==    by 0x5C7F61: PyUnicode_FromString (in /usr/bin/python3.10)
==249724==    by 0x5DAF1C: PyType_Ready (in /usr/bin/python3.10)
==249724==    by 0x5DB834: PyType_Ready (in /usr/bin/python3.10)
==249724==    by 0x6F1D8B: ??? (in /usr/bin/python3.10)
==249724==    by 0x6C3B38: ??? (in /usr/bin/python3.10)
==249724==    by 0x63082B: ??? (in /usr/bin/python3.10)
==249724==    by 0x6BF551: Py_InitializeFromConfig (in /usr/bin/python3.10)
==249724==    by 0x704415: ??? (in /usr/bin/python3.10)
==249724==    by 0x704470: ??? (in /usr/bin/python3.10)
==249724==    by 0x7044BC: Py_BytesMain (in /usr/bin/python3.10)
==249724==    by 0x489DD8F: (below main) (libc_start_call_main.h:58)
==249724== 
==249724== 672 bytes in 4 blocks are still reachable in loss record 47 of 99
==249724==    at 0x484DA83: calloc (in /usr/libexec/valgrind/vgpreload_memcheck-amd64-linux.so)
==249724==    by 0x40162DC: calloc (rtld-malloc.h:44)
==249724==    by 0x40162DC: _dl_check_map_versions (dl-version.c:273)
==249724==    by 0x400ED13: dl_open_worker_begin (dl-open.c:600)
==249724==    by 0x49E8A97: _dl_catch_exception (dl-error-skeleton.c:208)
==249724==    by 0x400DF99: dl_open_worker (dl-open.c:782)
==249724==    by 0x49E8A97: _dl_catch_exception (dl-error-skeleton.c:208)
==249724==    by 0x400E34D: _dl_open (dl-open.c:883)
==249724==    by 0x490463B: dlopen_doit (dlopen.c:56)
==249724==    by 0x49E8A97: _dl_catch_exception (dl-error-skeleton.c:208)
==249724==    by 0x49E8B62: _dl_catch_error (dl-error-skeleton.c:227)
==249724==    by 0x490412D: _dlerror_run (dlerror.c:138)
==249724==    by 0x49046C7: dlopen_implementation (dlopen.c:71)
==249724==    by 0x49046C7: dlopen@@GLIBC_2.34 (dlopen.c:81)
==249724== 
==249724== 718 bytes in 1 blocks are still reachable in loss record 48 of 99
==249724==    at 0x4848899: malloc (in /usr/libexec/valgrind/vgpreload_memcheck-amd64-linux.so)
==249724==    by 0x5C7F61: PyUnicode_FromString (in /usr/bin/python3.10)
==249724==    by 0x5DAF1C: PyType_Ready (in /usr/bin/python3.10)
==249724==    by 0x6F1E51: ??? (in /usr/bin/python3.10)
==249724==    by 0x6C3B38: ??? (in /usr/bin/python3.10)
==249724==    by 0x63082B: ??? (in /usr/bin/python3.10)
==249724==    by 0x6BF551: Py_InitializeFromConfig (in /usr/bin/python3.10)
==249724==    by 0x704415: ??? (in /usr/bin/python3.10)
==249724==    by 0x704470: ??? (in /usr/bin/python3.10)
==249724==    by 0x7044BC: Py_BytesMain (in /usr/bin/python3.10)
==249724==    by 0x489DD8F: (below main) (libc_start_call_main.h:58)
==249724== 
==249724== 720 bytes in 1 blocks are still reachable in loss record 49 of 99
==249724==    at 0x4848899: malloc (in /usr/libexec/valgrind/vgpreload_memcheck-amd64-linux.so)
==249724==    by 0x5F22D0: ??? (in /usr/bin/python3.10)
==249724==    by 0x6EE525: _PyStructSequence_InitType (in /usr/bin/python3.10)
==249724==    by 0x6C4790: ??? (in /usr/bin/python3.10)
==249724==    by 0x63082B: ??? (in /usr/bin/python3.10)
==249724==    by 0x6BF551: Py_InitializeFromConfig (in /usr/bin/python3.10)
==249724==    by 0x704415: ??? (in /usr/bin/python3.10)
==249724==    by 0x704470: ??? (in /usr/bin/python3.10)
==249724==    by 0x7044BC: Py_BytesMain (in /usr/bin/python3.10)
==249724==    by 0x489DD8F: (below main) (libc_start_call_main.h:58)
==249724== 
==249724== 768 bytes in 1 blocks are still reachable in loss record 50 of 99
==249724==    at 0x48487A9: malloc (in /usr/libexec/valgrind/vgpreload_memcheck-amd64-linux.so)
==249724==    by 0x5F2C57: ??? (in /usr/bin/python3.10)
==249724==    by 0x6145E3: _PyLong_New (in /usr/bin/python3.10)
==249724==    by 0x6C3902: ??? (in /usr/bin/python3.10)
==249724==    by 0x63082B: ??? (in /usr/bin/python3.10)
==249724==    by 0x6BF551: Py_InitializeFromConfig (in /usr/bin/python3.10)
==249724==    by 0x704415: ??? (in /usr/bin/python3.10)
==249724==    by 0x704470: ??? (in /usr/bin/python3.10)
==249724==    by 0x7044BC: Py_BytesMain (in /usr/bin/python3.10)
==249724==    by 0x489DD8F: (below main) (libc_start_call_main.h:58)
==249724== 
==249724== 827 bytes in 1 blocks are still reachable in loss record 51 of 99
==249724==    at 0x4848899: malloc (in /usr/libexec/valgrind/vgpreload_memcheck-amd64-linux.so)
==249724==    by 0x5C7F61: PyUnicode_FromString (in /usr/bin/python3.10)
==249724==    by 0x5DAF1C: PyType_Ready (in /usr/bin/python3.10)
==249724==    by 0x6C37B6: PyModule_AddType (in /usr/bin/python3.10)
==249724==    by 0x69D362: PyInit__io (in /usr/bin/python3.10)
==249724==    by 0x6CA547: ??? (in /usr/bin/python3.10)
==249724==    by 0x6CA60D: ??? (in /usr/bin/python3.10)
==249724==    by 0x53B136: ??? (in /usr/bin/python3.10)
==249724==    by 0x628A39: PyObject_Call (in /usr/bin/python3.10)
==249724==    by 0x5AFA8D: _PyEval_EvalFrameDefault (in /usr/bin/python3.10)
==249724==    by 0x628D5F: _PyFunction_Vectorcall (in /usr/bin/python3.10)
==249724==    by 0x5A9C1A: _PyEval_EvalFrameDefault (in /usr/bin/python3.10)
==249724== 
==249724== 944 bytes in 1 blocks are still reachable in loss record 52 of 99
==249724==    at 0x4848899: malloc (in /usr/libexec/valgrind/vgpreload_memcheck-amd64-linux.so)
==249724==    by 0x5E13F5: PyType_GenericAlloc (in /usr/bin/python3.10)
==249724==    by 0x6EAFCD: ??? (in /usr/bin/python3.10)
==249724==    by 0x5E2AE4: ??? (in /usr/bin/python3.10)
==249724==    by 0x629D23: _PyObject_MakeTpCall (in /usr/bin/python3.10)
==249724==    by 0x62B5D7: PyObject_CallFunction (in /usr/bin/python3.10)
==249724==    by 0x6CBCB5: PyErr_NewException (in /usr/bin/python3.10)
==249724==    by 0x471082: PyInit__socket (in /usr/bin/python3.10)
==249724==    by 0x6CA547: ??? (in /usr/bin/python3.10)
==249724==    by 0x6CA60D: ??? (in /usr/bin/python3.10)
==249724==    by 0x53B136: ??? (in /usr/bin/python3.10)
==249724==    by 0x628A39: PyObject_Call (in /usr/bin/python3.10)
==249724== 
==249724== 944 bytes in 1 blocks are still reachable in loss record 53 of 99
==249724==    at 0x4848899: malloc (in /usr/libexec/valgrind/vgpreload_memcheck-amd64-linux.so)
==249724==    by 0x5E13F5: PyType_GenericAlloc (in /usr/bin/python3.10)
==249724==    by 0x6EAFCD: ??? (in /usr/bin/python3.10)
==249724==    by 0x5E2AE4: ??? (in /usr/bin/python3.10)
==249724==    by 0x629D23: _PyObject_MakeTpCall (in /usr/bin/python3.10)
==249724==    by 0x62B5D7: PyObject_CallFunction (in /usr/bin/python3.10)
==249724==    by 0x6CBCB5: PyErr_NewException (in /usr/bin/python3.10)
==249724==    by 0x4710B8: PyInit__socket (in /usr/bin/python3.10)
==249724==    by 0x6CA547: ??? (in /usr/bin/python3.10)
==249724==    by 0x6CA60D: ??? (in /usr/bin/python3.10)
==249724==    by 0x53B136: ??? (in /usr/bin/python3.10)
==249724==    by 0x628A39: PyObject_Call (in /usr/bin/python3.10)
==249724== 
==249724== 1,112 bytes in 1 blocks are still reachable in loss record 54 of 99
==249724==    at 0x4848899: malloc (in /usr/libexec/valgrind/vgpreload_memcheck-amd64-linux.so)
==249724==    by 0x5F2EB0: PyObject_Malloc (in /usr/bin/python3.10)
==249724==    by 0x60211C: ??? (in /usr/bin/python3.10)
==249724==    by 0x5FF185: PyDict_SetDefault (in /usr/bin/python3.10)
==249724==    by 0x5DA11C: PyType_Ready (in /usr/bin/python3.10)
==249724==    by 0x6F1D55: ??? (in /usr/bin/python3.10)
==249724==    by 0x6C3B38: ??? (in /usr/bin/python3.10)
==249724==    by 0x63082B: ??? (in /usr/bin/python3.10)
==249724==    by 0x6BF551: Py_InitializeFromConfig (in /usr/bin/python3.10)
==249724==    by 0x704415: ??? (in /usr/bin/python3.10)
==249724==    by 0x704470: ??? (in /usr/bin/python3.10)
==249724==    by 0x7044BC: Py_BytesMain (in /usr/bin/python3.10)
==249724== 
==249724== 1,112 bytes in 1 blocks are still reachable in loss record 55 of 99
==249724==    at 0x4848899: malloc (in /usr/libexec/valgrind/vgpreload_memcheck-amd64-linux.so)
==249724==    by 0x5F2EB0: PyObject_Malloc (in /usr/bin/python3.10)
==249724==    by 0x60211C: ??? (in /usr/bin/python3.10)
==249724==    by 0x5FF185: PyDict_SetDefault (in /usr/bin/python3.10)
==249724==    by 0x5DADF5: PyType_Ready (in /usr/bin/python3.10)
==249724==    by 0x6F1D67: ??? (in /usr/bin/python3.10)
==249724==    by 0x6C3B38: ??? (in /usr/bin/python3.10)
==249724==    by 0x63082B: ??? (in /usr/bin/python3.10)
==249724==    by 0x6BF551: Py_InitializeFromConfig (in /usr/bin/python3.10)
==249724==    by 0x704415: ??? (in /usr/bin/python3.10)
==249724==    by 0x704470: ??? (in /usr/bin/python3.10)
==249724==    by 0x7044BC: Py_BytesMain (in /usr/bin/python3.10)
==249724== 
==249724== 1,112 bytes in 1 blocks are still reachable in loss record 56 of 99
==249724==    at 0x4848899: malloc (in /usr/libexec/valgrind/vgpreload_memcheck-amd64-linux.so)
==249724==    by 0x5F2EB0: PyObject_Malloc (in /usr/bin/python3.10)
==249724==    by 0x60211C: ??? (in /usr/bin/python3.10)
==249724==    by 0x5FF185: PyDict_SetDefault (in /usr/bin/python3.10)
==249724==    by 0x5DADF5: PyType_Ready (in /usr/bin/python3.10)
==249724==    by 0x6F1E63: ??? (in /usr/bin/python3.10)
==249724==    by 0x6C3B38: ??? (in /usr/bin/python3.10)
==249724==    by 0x63082B: ??? (in /usr/bin/python3.10)
==249724==    by 0x6BF551: Py_InitializeFromConfig (in /usr/bin/python3.10)
==249724==    by 0x704415: ??? (in /usr/bin/python3.10)
==249724==    by 0x704470: ??? (in /usr/bin/python3.10)
==249724==    by 0x7044BC: Py_BytesMain (in /usr/bin/python3.10)
==249724== 
==249724== 1,112 bytes in 1 blocks are still reachable in loss record 57 of 99
==249724==    at 0x4848899: malloc (in /usr/libexec/valgrind/vgpreload_memcheck-amd64-linux.so)
==249724==    by 0x5F2EB0: PyObject_Malloc (in /usr/bin/python3.10)
==249724==    by 0x60211C: ??? (in /usr/bin/python3.10)
==249724==    by 0x603263: PyDict_SetItem (in /usr/bin/python3.10)
==249724==    by 0x5DA030: PyType_Ready (in /usr/bin/python3.10)
==249724==    by 0x6F1E75: ??? (in /usr/bin/python3.10)
==249724==    by 0x6C3B38: ??? (in /usr/bin/python3.10)
==249724==    by 0x63082B: ??? (in /usr/bin/python3.10)
==249724==    by 0x6BF551: Py_InitializeFromConfig (in /usr/bin/python3.10)
==249724==    by 0x704415: ??? (in /usr/bin/python3.10)
==249724==    by 0x704470: ??? (in /usr/bin/python3.10)
==249724==    by 0x7044BC: Py_BytesMain (in /usr/bin/python3.10)
==249724== 
==249724== 1,112 bytes in 1 blocks are still reachable in loss record 58 of 99
==249724==    at 0x4848899: malloc (in /usr/libexec/valgrind/vgpreload_memcheck-amd64-linux.so)
==249724==    by 0x5F2EB0: PyObject_Malloc (in /usr/bin/python3.10)
==249724==    by 0x60211C: ??? (in /usr/bin/python3.10)
==249724==    by 0x5FF185: PyDict_SetDefault (in /usr/bin/python3.10)
==249724==    by 0x5DA11C: PyType_Ready (in /usr/bin/python3.10)
==249724==    by 0x6F1E99: ??? (in /usr/bin/python3.10)
==249724==    by 0x6C3B38: ??? (in /usr/bin/python3.10)
==249724==    by 0x63082B: ??? (in /usr/bin/python3.10)
==249724==    by 0x6BF551: Py_InitializeFromConfig (in /usr/bin/python3.10)
==249724==    by 0x704415: ??? (in /usr/bin/python3.10)
==249724==    by 0x704470: ??? (in /usr/bin/python3.10)
==249724==    by 0x7044BC: Py_BytesMain (in /usr/bin/python3.10)
==249724== 
==249724== 1,112 bytes in 1 blocks are still reachable in loss record 59 of 99
==249724==    at 0x4848899: malloc (in /usr/libexec/valgrind/vgpreload_memcheck-amd64-linux.so)
==249724==    by 0x5F2EB0: PyObject_Malloc (in /usr/bin/python3.10)
==249724==    by 0x60211C: ??? (in /usr/bin/python3.10)
==249724==    by 0x5FF185: PyDict_SetDefault (in /usr/bin/python3.10)
==249724==    by 0x5DA11C: PyType_Ready (in /usr/bin/python3.10)
==249724==    by 0x6F1EE1: ??? (in /usr/bin/python3.10)
==249724==    by 0x6C3B38: ??? (in /usr/bin/python3.10)
==249724==    by 0x63082B: ??? (in /usr/bin/python3.10)
==249724==    by 0x6BF551: Py_InitializeFromConfig (in /usr/bin/python3.10)
==249724==    by 0x704415: ??? (in /usr/bin/python3.10)
==249724==    by 0x704470: ??? (in /usr/bin/python3.10)
==249724==    by 0x7044BC: Py_BytesMain (in /usr/bin/python3.10)
==249724== 
==249724== 1,112 bytes in 1 blocks are still reachable in loss record 60 of 99
==249724==    at 0x4848899: malloc (in /usr/libexec/valgrind/vgpreload_memcheck-amd64-linux.so)
==249724==    by 0x5F2EB0: PyObject_Malloc (in /usr/bin/python3.10)
==249724==    by 0x60211C: ??? (in /usr/bin/python3.10)
==249724==    by 0x5FF185: PyDict_SetDefault (in /usr/bin/python3.10)
==249724==    by 0x5DA17B: PyType_Ready (in /usr/bin/python3.10)
==249724==    by 0x6F1EF3: ??? (in /usr/bin/python3.10)
==249724==    by 0x6C3B38: ??? (in /usr/bin/python3.10)
==249724==    by 0x63082B: ??? (in /usr/bin/python3.10)
==249724==    by 0x6BF551: Py_InitializeFromConfig (in /usr/bin/python3.10)
==249724==    by 0x704415: ??? (in /usr/bin/python3.10)
==249724==    by 0x704470: ??? (in /usr/bin/python3.10)
==249724==    by 0x7044BC: Py_BytesMain (in /usr/bin/python3.10)
==249724== 
==249724== 1,112 bytes in 1 blocks are still reachable in loss record 61 of 99
==249724==    at 0x4848899: malloc (in /usr/libexec/valgrind/vgpreload_memcheck-amd64-linux.so)
==249724==    by 0x5F2EB0: PyObject_Malloc (in /usr/bin/python3.10)
==249724==    by 0x60211C: ??? (in /usr/bin/python3.10)
==249724==    by 0x5FF185: PyDict_SetDefault (in /usr/bin/python3.10)
==249724==    by 0x5DA17B: PyType_Ready (in /usr/bin/python3.10)
==249724==    by 0x6F1F4D: ??? (in /usr/bin/python3.10)
==249724==    by 0x6C3B38: ??? (in /usr/bin/python3.10)
==249724==    by 0x63082B: ??? (in /usr/bin/python3.10)
==249724==    by 0x6BF551: Py_InitializeFromConfig (in /usr/bin/python3.10)
==249724==    by 0x704415: ??? (in /usr/bin/python3.10)
==249724==    by 0x704470: ??? (in /usr/bin/python3.10)
==249724==    by 0x7044BC: Py_BytesMain (in /usr/bin/python3.10)
==249724== 
==249724== 1,112 bytes in 1 blocks are still reachable in loss record 62 of 99
==249724==    at 0x4848899: malloc (in /usr/libexec/valgrind/vgpreload_memcheck-amd64-linux.so)
==249724==    by 0x5F2EB0: PyObject_Malloc (in /usr/bin/python3.10)
==249724==    by 0x60211C: ??? (in /usr/bin/python3.10)
==249724==    by 0x5FF185: PyDict_SetDefault (in /usr/bin/python3.10)
==249724==    by 0x5DA17B: PyType_Ready (in /usr/bin/python3.10)
==249724==    by 0x6F1FA7: ??? (in /usr/bin/python3.10)
==249724==    by 0x6C3B38: ??? (in /usr/bin/python3.10)
==249724==    by 0x63082B: ??? (in /usr/bin/python3.10)
==249724==    by 0x6BF551: Py_InitializeFromConfig (in /usr/bin/python3.10)
==249724==    by 0x704415: ??? (in /usr/bin/python3.10)
==249724==    by 0x704470: ??? (in /usr/bin/python3.10)
==249724==    by 0x7044BC: Py_BytesMain (in /usr/bin/python3.10)
==249724== 
==249724== 1,112 bytes in 1 blocks are still reachable in loss record 63 of 99
==249724==    at 0x4848899: malloc (in /usr/libexec/valgrind/vgpreload_memcheck-amd64-linux.so)
==249724==    by 0x5F2EB0: PyObject_Malloc (in /usr/bin/python3.10)
==249724==    by 0x60211C: ??? (in /usr/bin/python3.10)
==249724==    by 0x603263: PyDict_SetItem (in /usr/bin/python3.10)
==249724==    by 0x5DA030: PyType_Ready (in /usr/bin/python3.10)
==249724==    by 0x6F2025: ??? (in /usr/bin/python3.10)
==249724==    by 0x6C3B38: ??? (in /usr/bin/python3.10)
==249724==    by 0x63082B: ??? (in /usr/bin/python3.10)
==249724==    by 0x6BF551: Py_InitializeFromConfig (in /usr/bin/python3.10)
==249724==    by 0x704415: ??? (in /usr/bin/python3.10)
==249724==    by 0x704470: ??? (in /usr/bin/python3.10)
==249724==    by 0x7044BC: Py_BytesMain (in /usr/bin/python3.10)
==249724== 
==249724== 1,112 bytes in 1 blocks are still reachable in loss record 64 of 99
==249724==    at 0x4848899: malloc (in /usr/libexec/valgrind/vgpreload_memcheck-amd64-linux.so)
==249724==    by 0x5F2EB0: PyObject_Malloc (in /usr/bin/python3.10)
==249724==    by 0x60211C: ??? (in /usr/bin/python3.10)
==249724==    by 0x5FF185: PyDict_SetDefault (in /usr/bin/python3.10)
==249724==    by 0x5DA17B: PyType_Ready (in /usr/bin/python3.10)
==249724==    by 0x6F206D: ??? (in /usr/bin/python3.10)
==249724==    by 0x6C3B38: ??? (in /usr/bin/python3.10)
==249724==    by 0x63082B: ??? (in /usr/bin/python3.10)
==249724==    by 0x6BF551: Py_InitializeFromConfig (in /usr/bin/python3.10)
==249724==    by 0x704415: ??? (in /usr/bin/python3.10)
==249724==    by 0x704470: ??? (in /usr/bin/python3.10)
==249724==    by 0x7044BC: Py_BytesMain (in /usr/bin/python3.10)
==249724== 
==249724== 1,112 bytes in 1 blocks are still reachable in loss record 65 of 99
==249724==    at 0x4848899: malloc (in /usr/libexec/valgrind/vgpreload_memcheck-amd64-linux.so)
==249724==    by 0x5F2EB0: PyObject_Malloc (in /usr/bin/python3.10)
==249724==    by 0x60211C: ??? (in /usr/bin/python3.10)
==249724==    by 0x5FF185: PyDict_SetDefault (in /usr/bin/python3.10)
==249724==    by 0x5DA17B: PyType_Ready (in /usr/bin/python3.10)
==249724==    by 0x6F210F: ??? (in /usr/bin/python3.10)
==249724==    by 0x6C3B38: ??? (in /usr/bin/python3.10)
==249724==    by 0x63082B: ??? (in /usr/bin/python3.10)
==249724==    by 0x6BF551: Py_InitializeFromConfig (in /usr/bin/python3.10)
==249724==    by 0x704415: ??? (in /usr/bin/python3.10)
==249724==    by 0x704470: ??? (in /usr/bin/python3.10)
==249724==    by 0x7044BC: Py_BytesMain (in /usr/bin/python3.10)
==249724== 
==249724== 1,112 bytes in 1 blocks are still reachable in loss record 66 of 99
==249724==    at 0x4848899: malloc (in /usr/libexec/valgrind/vgpreload_memcheck-amd64-linux.so)
==249724==    by 0x5F2EB0: PyObject_Malloc (in /usr/bin/python3.10)
==249724==    by 0x60211C: ??? (in /usr/bin/python3.10)
==249724==    by 0x5FF185: PyDict_SetDefault (in /usr/bin/python3.10)
==249724==    by 0x5DADF5: PyType_Ready (in /usr/bin/python3.10)
==249724==    by 0x6F2157: ??? (in /usr/bin/python3.10)
==249724==    by 0x6C3B38: ??? (in /usr/bin/python3.10)
==249724==    by 0x63082B: ??? (in /usr/bin/python3.10)
==249724==    by 0x6BF551: Py_InitializeFromConfig (in /usr/bin/python3.10)
==249724==    by 0x704415: ??? (in /usr/bin/python3.10)
==249724==    by 0x704470: ??? (in /usr/bin/python3.10)
==249724==    by 0x7044BC: Py_BytesMain (in /usr/bin/python3.10)
==249724== 
==249724== 1,112 bytes in 1 blocks are still reachable in loss record 67 of 99
==249724==    at 0x4848899: malloc (in /usr/libexec/valgrind/vgpreload_memcheck-amd64-linux.so)
==249724==    by 0x5F2EB0: PyObject_Malloc (in /usr/bin/python3.10)
==249724==    by 0x60211C: ??? (in /usr/bin/python3.10)
==249724==    by 0x603263: PyDict_SetItem (in /usr/bin/python3.10)
==249724==    by 0x5DAF3C: PyType_Ready (in /usr/bin/python3.10)
==249724==    by 0x6F222F: ??? (in /usr/bin/python3.10)
==249724==    by 0x6C3B38: ??? (in /usr/bin/python3.10)
==249724==    by 0x63082B: ??? (in /usr/bin/python3.10)
==249724==    by 0x6BF551: Py_InitializeFromConfig (in /usr/bin/python3.10)
==249724==    by 0x704415: ??? (in /usr/bin/python3.10)
==249724==    by 0x704470: ??? (in /usr/bin/python3.10)
==249724==    by 0x7044BC: Py_BytesMain (in /usr/bin/python3.10)
==249724== 
==249724== 1,112 bytes in 1 blocks are still reachable in loss record 68 of 99
==249724==    at 0x4848899: malloc (in /usr/libexec/valgrind/vgpreload_memcheck-amd64-linux.so)
==249724==    by 0x5F2EB0: PyObject_Malloc (in /usr/bin/python3.10)
==249724==    by 0x60211C: ??? (in /usr/bin/python3.10)
==249724==    by 0x5FF185: PyDict_SetDefault (in /usr/bin/python3.10)
==249724==    by 0x5DA11C: PyType_Ready (in /usr/bin/python3.10)
==249724==    by 0x6F2277: ??? (in /usr/bin/python3.10)
==249724==    by 0x6C3B38: ??? (in /usr/bin/python3.10)
==249724==    by 0x63082B: ??? (in /usr/bin/python3.10)
==249724==    by 0x6BF551: Py_InitializeFromConfig (in /usr/bin/python3.10)
==249724==    by 0x704415: ??? (in /usr/bin/python3.10)
==249724==    by 0x704470: ??? (in /usr/bin/python3.10)
==249724==    by 0x7044BC: Py_BytesMain (in /usr/bin/python3.10)
==249724== 
==249724== 1,112 bytes in 1 blocks are still reachable in loss record 69 of 99
==249724==    at 0x4848899: malloc (in /usr/libexec/valgrind/vgpreload_memcheck-amd64-linux.so)
==249724==    by 0x5F2EB0: PyObject_Malloc (in /usr/bin/python3.10)
==249724==    by 0x60211C: ??? (in /usr/bin/python3.10)
==249724==    by 0x603263: PyDict_SetItem (in /usr/bin/python3.10)
==249724==    by 0x5FED10: PyDict_SetItemString (in /usr/bin/python3.10)
==249724==    by 0x6EE346: ??? (in /usr/bin/python3.10)
==249724==    by 0x6EE578: _PyStructSequence_InitType (in /usr/bin/python3.10)
==249724==    by 0x6C4790: ??? (in /usr/bin/python3.10)
==249724==    by 0x63082B: ??? (in /usr/bin/python3.10)
==249724==    by 0x6BF551: Py_InitializeFromConfig (in /usr/bin/python3.10)
==249724==    by 0x704415: ??? (in /usr/bin/python3.10)
==249724==    by 0x704470: ??? (in /usr/bin/python3.10)
==249724== 
==249724== 1,112 bytes in 1 blocks are still reachable in loss record 70 of 99
==249724==    at 0x4848899: malloc (in /usr/libexec/valgrind/vgpreload_memcheck-amd64-linux.so)
==249724==    by 0x5F2EB0: PyObject_Malloc (in /usr/bin/python3.10)
==249724==    by 0x60211C: ??? (in /usr/bin/python3.10)
==249724==    by 0x5FF185: PyDict_SetDefault (in /usr/bin/python3.10)
==249724==    by 0x5DA17B: PyType_Ready (in /usr/bin/python3.10)
==249724==    by 0x6C37B6: PyModule_AddType (in /usr/bin/python3.10)
==249724==    by 0x69D303: PyInit__io (in /usr/bin/python3.10)
==249724==    by 0x6CA547: ??? (in /usr/bin/python3.10)
==249724==    by 0x6CA60D: ??? (in /usr/bin/python3.10)
==249724==    by 0x53B136: ??? (in /usr/bin/python3.10)
==249724==    by 0x628A39: PyObject_Call (in /usr/bin/python3.10)
==249724==    by 0x5AFA8D: _PyEval_EvalFrameDefault (in /usr/bin/python3.10)
==249724== 
==249724== 1,112 bytes in 1 blocks are still reachable in loss record 71 of 99
==249724==    at 0x4848899: malloc (in /usr/libexec/valgrind/vgpreload_memcheck-amd64-linux.so)
==249724==    by 0x5F2EB0: PyObject_Malloc (in /usr/bin/python3.10)
==249724==    by 0x60211C: ??? (in /usr/bin/python3.10)
==249724==    by 0x5FF185: PyDict_SetDefault (in /usr/bin/python3.10)
==249724==    by 0x5DA11C: PyType_Ready (in /usr/bin/python3.10)
==249724==    by 0x6C37B6: PyModule_AddType (in /usr/bin/python3.10)
==249724==    by 0x69D362: PyInit__io (in /usr/bin/python3.10)
==249724==    by 0x6CA547: ??? (in /usr/bin/python3.10)
==249724==    by 0x6CA60D: ??? (in /usr/bin/python3.10)
==249724==    by 0x53B136: ??? (in /usr/bin/python3.10)
==249724==    by 0x628A39: PyObject_Call (in /usr/bin/python3.10)
==249724==    by 0x5AFA8D: _PyEval_EvalFrameDefault (in /usr/bin/python3.10)
==249724== 
==249724== 1,112 bytes in 1 blocks are still reachable in loss record 72 of 99
==249724==    at 0x4848899: malloc (in /usr/libexec/valgrind/vgpreload_memcheck-amd64-linux.so)
==249724==    by 0x5F2EB0: PyObject_Malloc (in /usr/bin/python3.10)
==249724==    by 0x60211C: ??? (in /usr/bin/python3.10)
==249724==    by 0x5FF185: PyDict_SetDefault (in /usr/bin/python3.10)
==249724==    by 0x5DA17B: PyType_Ready (in /usr/bin/python3.10)
==249724==    by 0x6C37B6: PyModule_AddType (in /usr/bin/python3.10)
==249724==    by 0x69D382: PyInit__io (in /usr/bin/python3.10)
==249724==    by 0x6CA547: ??? (in /usr/bin/python3.10)
==249724==    by 0x6CA60D: ??? (in /usr/bin/python3.10)
==249724==    by 0x53B136: ??? (in /usr/bin/python3.10)
==249724==    by 0x628A39: PyObject_Call (in /usr/bin/python3.10)
==249724==    by 0x5AFA8D: _PyEval_EvalFrameDefault (in /usr/bin/python3.10)
==249724== 
==249724== 1,112 bytes in 1 blocks are still reachable in loss record 73 of 99
==249724==    at 0x4848899: malloc (in /usr/libexec/valgrind/vgpreload_memcheck-amd64-linux.so)
==249724==    by 0x5F2EB0: PyObject_Malloc (in /usr/bin/python3.10)
==249724==    by 0x60211C: ??? (in /usr/bin/python3.10)
==249724==    by 0x5FF185: PyDict_SetDefault (in /usr/bin/python3.10)
==249724==    by 0x5DA17B: PyType_Ready (in /usr/bin/python3.10)
==249724==    by 0x6C37B6: PyModule_AddType (in /usr/bin/python3.10)
==249724==    by 0x69D3D4: PyInit__io (in /usr/bin/python3.10)
==249724==    by 0x6CA547: ??? (in /usr/bin/python3.10)
==249724==    by 0x6CA60D: ??? (in /usr/bin/python3.10)
==249724==    by 0x53B136: ??? (in /usr/bin/python3.10)
==249724==    by 0x628A39: PyObject_Call (in /usr/bin/python3.10)
==249724==    by 0x5AFA8D: _PyEval_EvalFrameDefault (in /usr/bin/python3.10)
==249724== 
==249724== 1,112 bytes in 1 blocks are still reachable in loss record 74 of 99
==249724==    at 0x4848899: malloc (in /usr/libexec/valgrind/vgpreload_memcheck-amd64-linux.so)
==249724==    by 0x5F2EB0: PyObject_Malloc (in /usr/bin/python3.10)
==249724==    by 0x60211C: ??? (in /usr/bin/python3.10)
==249724==    by 0x603263: PyDict_SetItem (in /usr/bin/python3.10)
==249724==    by 0x5DAF3C: PyType_Ready (in /usr/bin/python3.10)
==249724==    by 0x6C37B6: PyModule_AddType (in /usr/bin/python3.10)
==249724==    by 0x69D3F4: PyInit__io (in /usr/bin/python3.10)
==249724==    by 0x6CA547: ??? (in /usr/bin/python3.10)
==249724==    by 0x6CA60D: ??? (in /usr/bin/python3.10)
==249724==    by 0x53B136: ??? (in /usr/bin/python3.10)
==249724==    by 0x628A39: PyObject_Call (in /usr/bin/python3.10)
==249724==    by 0x5AFA8D: _PyEval_EvalFrameDefault (in /usr/bin/python3.10)
==249724== 
==249724== 1,112 bytes in 1 blocks are still reachable in loss record 75 of 99
==249724==    at 0x4848899: malloc (in /usr/libexec/valgrind/vgpreload_memcheck-amd64-linux.so)
==249724==    by 0x5F2EB0: PyObject_Malloc (in /usr/bin/python3.10)
==249724==    by 0x60211C: ??? (in /usr/bin/python3.10)
==249724==    by 0x5FF185: PyDict_SetDefault (in /usr/bin/python3.10)
==249724==    by 0x5DA17B: PyType_Ready (in /usr/bin/python3.10)
==249724==    by 0x6C37B6: PyModule_AddType (in /usr/bin/python3.10)
==249724==    by 0x69D434: PyInit__io (in /usr/bin/python3.10)
==249724==    by 0x6CA547: ??? (in /usr/bin/python3.10)
==249724==    by 0x6CA60D: ??? (in /usr/bin/python3.10)
==249724==    by 0x53B136: ??? (in /usr/bin/python3.10)
==249724==    by 0x628A39: PyObject_Call (in /usr/bin/python3.10)
==249724==    by 0x5AFA8D: _PyEval_EvalFrameDefault (in /usr/bin/python3.10)
==249724== 
==249724== 1,112 bytes in 1 blocks are still reachable in loss record 76 of 99
==249724==    at 0x4848899: malloc (in /usr/libexec/valgrind/vgpreload_memcheck-amd64-linux.so)
==249724==    by 0x5F2EB0: PyObject_Malloc (in /usr/bin/python3.10)
==249724==    by 0x60211C: ??? (in /usr/bin/python3.10)
==249724==    by 0x5FF185: PyDict_SetDefault (in /usr/bin/python3.10)
==249724==    by 0x5DADF5: PyType_Ready (in /usr/bin/python3.10)
==249724==    by 0x6C37B6: PyModule_AddType (in /usr/bin/python3.10)
==249724==    by 0x69D454: PyInit__io (in /usr/bin/python3.10)
==249724==    by 0x6CA547: ??? (in /usr/bin/python3.10)
==249724==    by 0x6CA60D: ??? (in /usr/bin/python3.10)
==249724==    by 0x53B136: ??? (in /usr/bin/python3.10)
==249724==    by 0x628A39: PyObject_Call (in /usr/bin/python3.10)
==249724==    by 0x5AFA8D: _PyEval_EvalFrameDefault (in /usr/bin/python3.10)
==249724== 
==249724== 1,112 bytes in 1 blocks are still reachable in loss record 77 of 99
==249724==    at 0x4848899: malloc (in /usr/libexec/valgrind/vgpreload_memcheck-amd64-linux.so)
==249724==    by 0x5F2EB0: PyObject_Malloc (in /usr/bin/python3.10)
==249724==    by 0x60211C: ??? (in /usr/bin/python3.10)
==249724==    by 0x603263: PyDict_SetItem (in /usr/bin/python3.10)
==249724==    by 0x6E760E: ??? (in /usr/bin/python3.10)
==249724==    by 0x5DA6C6: PyType_Ready (in /usr/bin/python3.10)
==249724==    by 0x6EB305: ??? (in /usr/bin/python3.10)
==249724==    by 0x5E2AE4: ??? (in /usr/bin/python3.10)
==249724==    by 0x629D23: _PyObject_MakeTpCall (in /usr/bin/python3.10)
==249724==    by 0x5A9C1A: _PyEval_EvalFrameDefault (in /usr/bin/python3.10)
==249724==    by 0x628D5F: _PyFunction_Vectorcall (in /usr/bin/python3.10)
==249724==    by 0x5A9C1A: _PyEval_EvalFrameDefault (in /usr/bin/python3.10)
==249724== 
==249724== 1,112 bytes in 1 blocks are still reachable in loss record 78 of 99
==249724==    at 0x4848899: malloc (in /usr/libexec/valgrind/vgpreload_memcheck-amd64-linux.so)
==249724==    by 0x5F2EB0: PyObject_Malloc (in /usr/bin/python3.10)
==249724==    by 0x60211C: ??? (in /usr/bin/python3.10)
==249724==    by 0x5FF185: PyDict_SetDefault (in /usr/bin/python3.10)
==249724==    by 0x5DA17B: PyType_Ready (in /usr/bin/python3.10)
==249724==    by 0x4F8DF2: ??? (in /usr/bin/python3.10)
==249724==    by 0x6EBF89: ??? (in /usr/bin/python3.10)
==249724==    by 0x5E2AE4: ??? (in /usr/bin/python3.10)
==249724==    by 0x629D23: _PyObject_MakeTpCall (in /usr/bin/python3.10)
==249724==    by 0x62B898: _PyObject_FastCallDictTstate (in /usr/bin/python3.10)
==249724==    by 0x646783: ??? (in /usr/bin/python3.10)
==249724==    by 0x53AF63: ??? (in /usr/bin/python3.10)
==249724== 
==249724== 1,112 bytes in 1 blocks are still reachable in loss record 79 of 99
==249724==    at 0x4848899: malloc (in /usr/libexec/valgrind/vgpreload_memcheck-amd64-linux.so)
==249724==    by 0x5F2EB0: PyObject_Malloc (in /usr/bin/python3.10)
==249724==    by 0x60211C: ??? (in /usr/bin/python3.10)
==249724==    by 0x603263: PyDict_SetItem (in /usr/bin/python3.10)
==249724==    by 0x5DA030: PyType_Ready (in /usr/bin/python3.10)
==249724==    by 0x6C37B6: PyModule_AddType (in /usr/bin/python3.10)
==249724==    by 0x6A68B5: PyInit__datetime (in /usr/bin/python3.10)
==249724==    by 0x6CA547: ??? (in /usr/bin/python3.10)
==249724==    by 0x6CA60D: ??? (in /usr/bin/python3.10)
==249724==    by 0x53B136: ??? (in /usr/bin/python3.10)
==249724==    by 0x628A39: PyObject_Call (in /usr/bin/python3.10)
==249724==    by 0x5AFA8D: _PyEval_EvalFrameDefault (in /usr/bin/python3.10)
==249724== 
==249724== 1,284 bytes in 1 blocks are still reachable in loss record 80 of 99
==249724==    at 0x4848899: malloc (in /usr/libexec/valgrind/vgpreload_memcheck-amd64-linux.so)
==249724==    by 0x5C7F61: PyUnicode_FromString (in /usr/bin/python3.10)
==249724==    by 0x5DAF1C: PyType_Ready (in /usr/bin/python3.10)
==249724==    by 0x6C37B6: PyModule_AddType (in /usr/bin/python3.10)
==249724==    by 0x69D303: PyInit__io (in /usr/bin/python3.10)
==249724==    by 0x6CA547: ??? (in /usr/bin/python3.10)
==249724==    by 0x6CA60D: ??? (in /usr/bin/python3.10)
==249724==    by 0x53B136: ??? (in /usr/bin/python3.10)
==249724==    by 0x628A39: PyObject_Call (in /usr/bin/python3.10)
==249724==    by 0x5AFA8D: _PyEval_EvalFrameDefault (in /usr/bin/python3.10)
==249724==    by 0x628D5F: _PyFunction_Vectorcall (in /usr/bin/python3.10)
==249724==    by 0x5A9C1A: _PyEval_EvalFrameDefault (in /usr/bin/python3.10)
==249724== 
==249724== 1,332 bytes in 2 blocks are still reachable in loss record 81 of 99
==249724==    at 0x4848899: malloc (in /usr/libexec/valgrind/vgpreload_memcheck-amd64-linux.so)
==249724==    by 0x5C7F61: PyUnicode_FromString (in /usr/bin/python3.10)
==249724==    by 0x5DAF1C: PyType_Ready (in /usr/bin/python3.10)
==249724==    by 0x6C37B6: PyModule_AddType (in /usr/bin/python3.10)
==249724==    by 0x67AC3D: ??? (in /usr/bin/python3.10)
==249724==    by 0x6F2D02: PyModule_ExecDef (in /usr/bin/python3.10)
==249724==    by 0x6C996F: ??? (in /usr/bin/python3.10)
==249724==    by 0x53B136: ??? (in /usr/bin/python3.10)
==249724==    by 0x628A39: PyObject_Call (in /usr/bin/python3.10)
==249724==    by 0x5AFA8D: _PyEval_EvalFrameDefault (in /usr/bin/python3.10)
==249724==    by 0x628D5F: _PyFunction_Vectorcall (in /usr/bin/python3.10)
==249724==    by 0x5A9C1A: _PyEval_EvalFrameDefault (in /usr/bin/python3.10)
==249724== 
==249724== 1,393 bytes in 1 blocks are still reachable in loss record 82 of 99
==249724==    at 0x4848899: malloc (in /usr/libexec/valgrind/vgpreload_memcheck-amd64-linux.so)
==249724==    by 0x5C7F61: PyUnicode_FromString (in /usr/bin/python3.10)
==249724==    by 0x5DAF1C: PyType_Ready (in /usr/bin/python3.10)
==249724==    by 0x6C37B6: PyModule_AddType (in /usr/bin/python3.10)
==249724==    by 0x69D454: PyInit__io (in /usr/bin/python3.10)
==249724==    by 0x6CA547: ??? (in /usr/bin/python3.10)
==249724==    by 0x6CA60D: ??? (in /usr/bin/python3.10)
==249724==    by 0x53B136: ??? (in /usr/bin/python3.10)
==249724==    by 0x628A39: PyObject_Call (in /usr/bin/python3.10)
==249724==    by 0x5AFA8D: _PyEval_EvalFrameDefault (in /usr/bin/python3.10)
==249724==    by 0x628D5F: _PyFunction_Vectorcall (in /usr/bin/python3.10)
==249724==    by 0x5A9C1A: _PyEval_EvalFrameDefault (in /usr/bin/python3.10)
==249724== 
==249724== 1,688 bytes in 2 blocks are still reachable in loss record 83 of 99
==249724==    at 0x4848899: malloc (in /usr/libexec/valgrind/vgpreload_memcheck-amd64-linux.so)
==249724==    by 0x5F2EB0: PyObject_Malloc (in /usr/bin/python3.10)
==249724==    by 0x60211C: ??? (in /usr/bin/python3.10)
==249724==    by 0x5FF185: PyDict_SetDefault (in /usr/bin/python3.10)
==249724==    by 0x5DA17B: PyType_Ready (in /usr/bin/python3.10)
==249724==    by 0x6C37B6: PyModule_AddType (in /usr/bin/python3.10)
==249724==    by 0x6A68B5: PyInit__datetime (in /usr/bin/python3.10)
==249724==    by 0x6CA547: ??? (in /usr/bin/python3.10)
==249724==    by 0x6CA60D: ??? (in /usr/bin/python3.10)
==249724==    by 0x53B136: ??? (in /usr/bin/python3.10)
==249724==    by 0x628A39: PyObject_Call (in /usr/bin/python3.10)
==249724==    by 0x5AFA8D: _PyEval_EvalFrameDefault (in /usr/bin/python3.10)
==249724== 
==249724== 2,048 bytes in 1 blocks are still reachable in loss record 84 of 99
==249724==    at 0x484DA83: calloc (in /usr/libexec/valgrind/vgpreload_memcheck-amd64-linux.so)
==249724==    by 0x6F0F69: ??? (in /usr/bin/python3.10)
==249724==    by 0x5F2B5D: ??? (in /usr/bin/python3.10)
==249724==    by 0x6145E3: _PyLong_New (in /usr/bin/python3.10)
==249724==    by 0x6C3902: ??? (in /usr/bin/python3.10)
==249724==    by 0x63082B: ??? (in /usr/bin/python3.10)
==249724==    by 0x6BF551: Py_InitializeFromConfig (in /usr/bin/python3.10)
==249724==    by 0x704415: ??? (in /usr/bin/python3.10)
==249724==    by 0x704470: ??? (in /usr/bin/python3.10)
==249724==    by 0x7044BC: Py_BytesMain (in /usr/bin/python3.10)
==249724==    by 0x489DD8F: (below main) (libc_start_call_main.h:58)
==249724== 
==249724== 2,181 bytes in 1 blocks are still reachable in loss record 85 of 99
==249724==    at 0x4848899: malloc (in /usr/libexec/valgrind/vgpreload_memcheck-amd64-linux.so)
==249724==    by 0x5C7F61: PyUnicode_FromString (in /usr/bin/python3.10)
==249724==    by 0x5DAF1C: PyType_Ready (in /usr/bin/python3.10)
==249724==    by 0x4F8DF2: ??? (in /usr/bin/python3.10)
==249724==    by 0x6EBF89: ??? (in /usr/bin/python3.10)
==249724==    by 0x5E2AE4: ??? (in /usr/bin/python3.10)
==249724==    by 0x629D23: _PyObject_MakeTpCall (in /usr/bin/python3.10)
==249724==    by 0x62B898: _PyObject_FastCallDictTstate (in /usr/bin/python3.10)
==249724==    by 0x646783: ??? (in /usr/bin/python3.10)
==249724==    by 0x53AF63: ??? (in /usr/bin/python3.10)
==249724==    by 0x5A9C1A: _PyEval_EvalFrameDefault (in /usr/bin/python3.10)
==249724==    by 0x5A8BF0: ??? (in /usr/bin/python3.10)
==249724== 
==249724== 2,208 bytes in 1 blocks are still reachable in loss record 86 of 99
==249724==    at 0x4848899: malloc (in /usr/libexec/valgrind/vgpreload_memcheck-amd64-linux.so)
==249724==    by 0x5F2EB0: PyObject_Malloc (in /usr/bin/python3.10)
==249724==    by 0x60211C: ??? (in /usr/bin/python3.10)
==249724==    by 0x603263: PyDict_SetItem (in /usr/bin/python3.10)
==249724==    by 0x5DA030: PyType_Ready (in /usr/bin/python3.10)
==249724==    by 0x5DB834: PyType_Ready (in /usr/bin/python3.10)
==249724==    by 0x6F1D8B: ??? (in /usr/bin/python3.10)
==249724==    by 0x6C3B38: ??? (in /usr/bin/python3.10)
==249724==    by 0x63082B: ??? (in /usr/bin/python3.10)
==249724==    by 0x6BF551: Py_InitializeFromConfig (in /usr/bin/python3.10)
==249724==    by 0x704415: ??? (in /usr/bin/python3.10)
==249724==    by 0x704470: ??? (in /usr/bin/python3.10)
==249724== 
==249724== 2,208 bytes in 1 blocks are still reachable in loss record 87 of 99
==249724==    at 0x4848899: malloc (in /usr/libexec/valgrind/vgpreload_memcheck-amd64-linux.so)
==249724==    by 0x5F2EB0: PyObject_Malloc (in /usr/bin/python3.10)
==249724==    by 0x60211C: ??? (in /usr/bin/python3.10)
==249724==    by 0x5FF185: PyDict_SetDefault (in /usr/bin/python3.10)
==249724==    by 0x5DA17B: PyType_Ready (in /usr/bin/python3.10)
==249724==    by 0x6F1DAF: ??? (in /usr/bin/python3.10)
==249724==    by 0x6C3B38: ??? (in /usr/bin/python3.10)
==249724==    by 0x63082B: ??? (in /usr/bin/python3.10)
==249724==    by 0x6BF551: Py_InitializeFromConfig (in /usr/bin/python3.10)
==249724==    by 0x704415: ??? (in /usr/bin/python3.10)
==249724==    by 0x704470: ??? (in /usr/bin/python3.10)
==249724==    by 0x7044BC: Py_BytesMain (in /usr/bin/python3.10)
==249724== 
==249724== 2,208 bytes in 1 blocks are still reachable in loss record 88 of 99
==249724==    at 0x4848899: malloc (in /usr/libexec/valgrind/vgpreload_memcheck-amd64-linux.so)
==249724==    by 0x5F2EB0: PyObject_Malloc (in /usr/bin/python3.10)
==249724==    by 0x60211C: ??? (in /usr/bin/python3.10)
==249724==    by 0x5FF185: PyDict_SetDefault (in /usr/bin/python3.10)
==249724==    by 0x5DA17B: PyType_Ready (in /usr/bin/python3.10)
==249724==    by 0x6F1DD3: ??? (in /usr/bin/python3.10)
==249724==    by 0x6C3B38: ??? (in /usr/bin/python3.10)
==249724==    by 0x63082B: ??? (in /usr/bin/python3.10)
==249724==    by 0x6BF551: Py_InitializeFromConfig (in /usr/bin/python3.10)
==249724==    by 0x704415: ??? (in /usr/bin/python3.10)
==249724==    by 0x704470: ??? (in /usr/bin/python3.10)
==249724==    by 0x7044BC: Py_BytesMain (in /usr/bin/python3.10)
==249724== 
==249724== 2,208 bytes in 1 blocks are still reachable in loss record 89 of 99
==249724==    at 0x4848899: malloc (in /usr/libexec/valgrind/vgpreload_memcheck-amd64-linux.so)
==249724==    by 0x5F2EB0: PyObject_Malloc (in /usr/bin/python3.10)
==249724==    by 0x60211C: ??? (in /usr/bin/python3.10)
==249724==    by 0x5FF185: PyDict_SetDefault (in /usr/bin/python3.10)
==249724==    by 0x5DA17B: PyType_Ready (in /usr/bin/python3.10)
==249724==    by 0x6F1F83: ??? (in /usr/bin/python3.10)
==249724==    by 0x6C3B38: ??? (in /usr/bin/python3.10)
==249724==    by 0x63082B: ??? (in /usr/bin/python3.10)
==249724==    by 0x6BF551: Py_InitializeFromConfig (in /usr/bin/python3.10)
==249724==    by 0x704415: ??? (in /usr/bin/python3.10)
==249724==    by 0x704470: ??? (in /usr/bin/python3.10)
==249724==    by 0x7044BC: Py_BytesMain (in /usr/bin/python3.10)
==249724== 
==249724== 2,208 bytes in 1 blocks are still reachable in loss record 90 of 99
==249724==    at 0x4848899: malloc (in /usr/libexec/valgrind/vgpreload_memcheck-amd64-linux.so)
==249724==    by 0x5F2EB0: PyObject_Malloc (in /usr/bin/python3.10)
==249724==    by 0x60211C: ??? (in /usr/bin/python3.10)
==249724==    by 0x5FF185: PyDict_SetDefault (in /usr/bin/python3.10)
==249724==    by 0x5DA17B: PyType_Ready (in /usr/bin/python3.10)
==249724==    by 0x6F21B1: ??? (in /usr/bin/python3.10)
==249724==    by 0x6C3B38: ??? (in /usr/bin/python3.10)
==249724==    by 0x63082B: ??? (in /usr/bin/python3.10)
==249724==    by 0x6BF551: Py_InitializeFromConfig (in /usr/bin/python3.10)
==249724==    by 0x704415: ??? (in /usr/bin/python3.10)
==249724==    by 0x704470: ??? (in /usr/bin/python3.10)
==249724==    by 0x7044BC: Py_BytesMain (in /usr/bin/python3.10)
==249724== 
==249724== 2,208 bytes in 1 blocks are still reachable in loss record 91 of 99
==249724==    at 0x4848899: malloc (in /usr/libexec/valgrind/vgpreload_memcheck-amd64-linux.so)
==249724==    by 0x5F2EB0: PyObject_Malloc (in /usr/bin/python3.10)
==249724==    by 0x60211C: ??? (in /usr/bin/python3.10)
==249724==    by 0x5FF185: PyDict_SetDefault (in /usr/bin/python3.10)
==249724==    by 0x5DA17B: PyType_Ready (in /usr/bin/python3.10)
==249724==    by 0x6F2253: ??? (in /usr/bin/python3.10)
==249724==    by 0x6C3B38: ??? (in /usr/bin/python3.10)
==249724==    by 0x63082B: ??? (in /usr/bin/python3.10)
==249724==    by 0x6BF551: Py_InitializeFromConfig (in /usr/bin/python3.10)
==249724==    by 0x704415: ??? (in /usr/bin/python3.10)
==249724==    by 0x704470: ??? (in /usr/bin/python3.10)
==249724==    by 0x7044BC: Py_BytesMain (in /usr/bin/python3.10)
==249724== 
==249724== 2,208 bytes in 1 blocks are still reachable in loss record 92 of 99
==249724==    at 0x4848899: malloc (in /usr/libexec/valgrind/vgpreload_memcheck-amd64-linux.so)
==249724==    by 0x5F2EB0: PyObject_Malloc (in /usr/bin/python3.10)
==249724==    by 0x60211C: ??? (in /usr/bin/python3.10)
==249724==    by 0x603263: PyDict_SetItem (in /usr/bin/python3.10)
==249724==    by 0x5DA030: PyType_Ready (in /usr/bin/python3.10)
==249724==    by 0x6F234F: ??? (in /usr/bin/python3.10)
==249724==    by 0x6C3B38: ??? (in /usr/bin/python3.10)
==249724==    by 0x63082B: ??? (in /usr/bin/python3.10)
==249724==    by 0x6BF551: Py_InitializeFromConfig (in /usr/bin/python3.10)
==249724==    by 0x704415: ??? (in /usr/bin/python3.10)
==249724==    by 0x704470: ??? (in /usr/bin/python3.10)
==249724==    by 0x7044BC: Py_BytesMain (in /usr/bin/python3.10)
==249724== 
==249724== 2,208 bytes in 1 blocks are still reachable in loss record 93 of 99
==249724==    at 0x4848899: malloc (in /usr/libexec/valgrind/vgpreload_memcheck-amd64-linux.so)
==249724==    by 0x5F2EB0: PyObject_Malloc (in /usr/bin/python3.10)
==249724==    by 0x60211C: ??? (in /usr/bin/python3.10)
==249724==    by 0x603263: PyDict_SetItem (in /usr/bin/python3.10)
==249724==    by 0x5DA030: PyType_Ready (in /usr/bin/python3.10)
==249724==    by 0x6F2361: ??? (in /usr/bin/python3.10)
==249724==    by 0x6C3B38: ??? (in /usr/bin/python3.10)
==249724==    by 0x63082B: ??? (in /usr/bin/python3.10)
==249724==    by 0x6BF551: Py_InitializeFromConfig (in /usr/bin/python3.10)
==249724==    by 0x704415: ??? (in /usr/bin/python3.10)
==249724==    by 0x704470: ??? (in /usr/bin/python3.10)
==249724==    by 0x7044BC: Py_BytesMain (in /usr/bin/python3.10)
==249724== 
==249724== 2,208 bytes in 1 blocks are still reachable in loss record 94 of 99
==249724==    at 0x4848899: malloc (in /usr/libexec/valgrind/vgpreload_memcheck-amd64-linux.so)
==249724==    by 0x5F2EB0: PyObject_Malloc (in /usr/bin/python3.10)
==249724==    by 0x60211C: ??? (in /usr/bin/python3.10)
==249724==    by 0x5FF185: PyDict_SetDefault (in /usr/bin/python3.10)
==249724==    by 0x5DA11C: PyType_Ready (in /usr/bin/python3.10)
==249724==    by 0x6C37B6: PyModule_AddType (in /usr/bin/python3.10)
==249724==    by 0x6AD066: ??? (in /usr/bin/python3.10)
==249724==    by 0x6F2D02: PyModule_ExecDef (in /usr/bin/python3.10)
==249724==    by 0x6C996F: ??? (in /usr/bin/python3.10)
==249724==    by 0x53B136: ??? (in /usr/bin/python3.10)
==249724==    by 0x628A39: PyObject_Call (in /usr/bin/python3.10)
==249724==    by 0x5AFA8D: _PyEval_EvalFrameDefault (in /usr/bin/python3.10)
==249724== 
==249724== 2,411 bytes in 2 blocks are still reachable in loss record 95 of 99
==249724==    at 0x484DA83: calloc (in /usr/libexec/valgrind/vgpreload_memcheck-amd64-linux.so)
==249724==    by 0x400DA02: calloc (rtld-malloc.h:44)
==249724==    by 0x400DA02: _dl_new_object (dl-object.c:92)
==249724==    by 0x4008C82: _dl_map_object_from_fd (dl-load.c:1063)
==249724==    by 0x400A600: _dl_map_object (dl-load.c:2327)
==249724==    by 0x4003494: openaux (dl-deps.c:64)
==249724==    by 0x49E8A97: _dl_catch_exception (dl-error-skeleton.c:208)
==249724==    by 0x4003C7B: _dl_map_object_deps (dl-deps.c:248)
==249724==    by 0x400EA0E: dl_open_worker_begin (dl-open.c:592)
==249724==    by 0x49E8A97: _dl_catch_exception (dl-error-skeleton.c:208)
==249724==    by 0x400DF99: dl_open_worker (dl-open.c:782)
==249724==    by 0x49E8A97: _dl_catch_exception (dl-error-skeleton.c:208)
==249724==    by 0x400E34D: _dl_open (dl-open.c:883)
==249724== 
==249724== 2,523 bytes in 2 blocks are still reachable in loss record 96 of 99
==249724==    at 0x484DA83: calloc (in /usr/libexec/valgrind/vgpreload_memcheck-amd64-linux.so)
==249724==    by 0x400DA02: calloc (rtld-malloc.h:44)
==249724==    by 0x400DA02: _dl_new_object (dl-object.c:92)
==249724==    by 0x4008C82: _dl_map_object_from_fd (dl-load.c:1063)
==249724==    by 0x400A600: _dl_map_object (dl-load.c:2327)
==249724==    by 0x400E9A8: dl_open_worker_begin (dl-open.c:534)
==249724==    by 0x49E8A97: _dl_catch_exception (dl-error-skeleton.c:208)
==249724==    by 0x400DF99: dl_open_worker (dl-open.c:782)
==249724==    by 0x49E8A97: _dl_catch_exception (dl-error-skeleton.c:208)
==249724==    by 0x400E34D: _dl_open (dl-open.c:883)
==249724==    by 0x490463B: dlopen_doit (dlopen.c:56)
==249724==    by 0x49E8A97: _dl_catch_exception (dl-error-skeleton.c:208)
==249724==    by 0x49E8B62: _dl_catch_error (dl-error-skeleton.c:227)
==249724== 
==249724== 3,320 bytes in 2 blocks are still reachable in loss record 97 of 99
==249724==    at 0x4848899: malloc (in /usr/libexec/valgrind/vgpreload_memcheck-amd64-linux.so)
==249724==    by 0x5F2EB0: PyObject_Malloc (in /usr/bin/python3.10)
==249724==    by 0x60211C: ??? (in /usr/bin/python3.10)
==249724==    by 0x5FF185: PyDict_SetDefault (in /usr/bin/python3.10)
==249724==    by 0x5DA11C: PyType_Ready (in /usr/bin/python3.10)
==249724==    by 0x6C37B6: PyModule_AddType (in /usr/bin/python3.10)
==249724==    by 0x6A68B5: PyInit__datetime (in /usr/bin/python3.10)
==249724==    by 0x6CA547: ??? (in /usr/bin/python3.10)
==249724==    by 0x6CA60D: ??? (in /usr/bin/python3.10)
==249724==    by 0x53B136: ??? (in /usr/bin/python3.10)
==249724==    by 0x628A39: PyObject_Call (in /usr/bin/python3.10)
==249724==    by 0x5AFA8D: _PyEval_EvalFrameDefault (in /usr/bin/python3.10)
==249724== 
==249724== 8,192 bytes in 1 blocks are still reachable in loss record 98 of 99
==249724==    at 0x484DA83: calloc (in /usr/libexec/valgrind/vgpreload_memcheck-amd64-linux.so)
==249724==    by 0x6F0FA1: ??? (in /usr/bin/python3.10)
==249724==    by 0x5F2B5D: ??? (in /usr/bin/python3.10)
==249724==    by 0x6145E3: _PyLong_New (in /usr/bin/python3.10)
==249724==    by 0x6C3902: ??? (in /usr/bin/python3.10)
==249724==    by 0x63082B: ??? (in /usr/bin/python3.10)
==249724==    by 0x6BF551: Py_InitializeFromConfig (in /usr/bin/python3.10)
==249724==    by 0x704415: ??? (in /usr/bin/python3.10)
==249724==    by 0x704470: ??? (in /usr/bin/python3.10)
==249724==    by 0x7044BC: Py_BytesMain (in /usr/bin/python3.10)
==249724==    by 0x489DD8F: (below main) (libc_start_call_main.h:58)
==249724== 
==249724== 10,360 bytes in 2 blocks are still reachable in loss record 99 of 99
==249724==    at 0x4848899: malloc (in /usr/libexec/valgrind/vgpreload_memcheck-amd64-linux.so)
==249724==    by 0x5F2EB0: PyObject_Malloc (in /usr/bin/python3.10)
==249724==    by 0x60211C: ??? (in /usr/bin/python3.10)
==249724==    by 0x603263: PyDict_SetItem (in /usr/bin/python3.10)
==249724==    by 0x6E760E: ??? (in /usr/bin/python3.10)
==249724==    by 0x5DA6C6: PyType_Ready (in /usr/bin/python3.10)
==249724==    by 0x6EB305: ??? (in /usr/bin/python3.10)
==249724==    by 0x5E2AE4: ??? (in /usr/bin/python3.10)
==249724==    by 0x629D23: _PyObject_MakeTpCall (in /usr/bin/python3.10)
==249724==    by 0x62B898: _PyObject_FastCallDictTstate (in /usr/bin/python3.10)
==249724==    by 0x646783: ??? (in /usr/bin/python3.10)
==249724==    by 0x53AF63: ??? (in /usr/bin/python3.10)
==249724== 
==249724== LEAK SUMMARY:
==249724==    definitely lost: 0 bytes in 0 blocks
==249724==    indirectly lost: 0 bytes in 0 blocks
==249724==      possibly lost: 0 bytes in 0 blocks
==249724==    still reachable: 115,753 bytes in 112 blocks
==249724==         suppressed: 0 bytes in 0 blocks
==249724== 
==249724== For lists of detected and suppressed errors, rerun with: -s
==249724== ERROR SUMMARY: 0 errors from 0 contexts (suppressed: 0 from 0)
wevserv: Webserv::checkChildsEnd: waitpid: 
webserv: Webserv::start: epoll_wait: Interrupted system call
